Workbook

Sheet P Chart
A1: S NO | B1: DATE | C1: Total Inspection | D1: REJECTION | E1: PPM | F1: Crack | G1: Flange Short | H1: Total Defects | I1: DATE | J1: Proportion | K1: UCL | L1: LCL | M1: CL
A2: 1 | B2: 1 | C2: 51245 | D2: 90 | E2: 1756.2689 | F2: 0 | G2: 6 | H2: =F2+G2 -> 6 | I2: 1 | J2: =H2/C2 -> 0.00011708459 | K2: =$M$2+3*SQRT(($M$2*(1-$M$2))/C2) -> 0.00060227822 | L2: =MAX(0,$M$2-3*SQRT(($M$2*(1-$M$2))/C2)) -> 0.00010421219 | M2: =$H$33/$C$33 -> 0.00035324521
A3: 2 | B3: 2 | C3: 53413 | D3: 95 | E3: 1778.5932 | F3: 2 | G3: 30 | H3: =F3+G3 -> 32 | I3: 2 | J3: =H3/C3 -> 0.00059910509 | K3: =$M$2+3*SQRT(($M$2*(1-$M$2))/C3) -> 0.00059717182 | L3: =MAX(0,$M$2-3*SQRT(($M$2*(1-$M$2))/C3)) -> 0.00010931859 | M3: =$H$33/$C$33 -> 0.00035324521
A4: 3 | B4: 3 | C4: 37642 | D4: 88 | E4: 2337.8141 | F4: 12 | G4: 1 | H4: =F4+G4 -> 13 | I4: 3 | J4: =H4/C4 -> 0.00034535891 | K4: =$M$2+3*SQRT(($M$2*(1-$M$2))/C4) -> 0.00064381223 | L4: =MAX(0,$M$2-3*SQRT(($M$2*(1-$M$2))/C4)) -> 6.2678181e-05 | M4: =$H$33/$C$33 -> 0.00035324521
A5: 4 | B5: 4 | C5: 54309 | D5: 85 | E5: 1565.1181 | F5: 10 | G5: 15 | H5: =F5+G5 -> 25 | I5: 4 | J5: =H5/C5 -> 0.00046032886 | K5: =$M$2+3*SQRT(($M$2*(1-$M$2))/C5) -> 0.00059515128 | L5: =MAX(0,$M$2-3*SQRT(($M$2*(1-$M$2))/C5)) -> 0.00011133913 | M5: =$H$33/$C$33 -> 0.00035324521
A6: 5 | B6: 5 | C6: 57829 | D6: 142 | E6: 2455.5154 | F6: 10 | G6: 24 | H6: =F6+G6 -> 34 | I6: 5 | J6: =H6/C6 -> 0.00058794031 | K6: =$M$2+3*SQRT(($M$2*(1-$M$2))/C6) -> 0.0005876734 | L6: =MAX(0,$M$2-3*SQRT(($M$2*(1-$M$2))/C6)) -> 0.00011881702 | M6: =$H$33/$C$33 -> 0.00035324521
A7: 6 | B7: 6 | C7: 61375 | D7: 50 | E7: 814.66395 | F7: 9 | G7: 11 | H7: =F7+G7 -> 20 | I7: 6 | J7: =H7/C7 -> 0.00032586558 | K7: =$M$2+3*SQRT(($M$2*(1-$M$2))/C7) -> 0.00058080049 | L7: =MAX(0,$M$2-3*SQRT(($M$2*(1-$M$2))/C7)) -> 0.00012568993 | M7: =$H$33/$C$33 -> 0.00035324521
A8: 7 | B8: 7 | C8: 58311 | D8: 173 | E8: 2966.8502 | F8: 5 | G8: 8 | H8: =F8+G8 -> 13 | I8: 7 | J8: =H8/C8 -> 0.0002229425 | K8: =$M$2+3*SQRT(($M$2*(1-$M$2))/C8) -> 0.00058670249 | L8: =MAX(0,$M$2-3*SQRT(($M$2*(1-$M$2))/C8)) -> 0.00011978792 | M8: =$H$33/$C$33 -> 0.00035324521
A9: 8 | B9: 8 | C9: 55771 | D9: 80 | E9: 1434.4373 | F9: 2 | G9: 11 | H9: =F9+G9 -> 13 | I9: 8 | J9: =H9/C9 -> 0.00023309605 | K9: =$M$2+3*SQRT(($M$2*(1-$M$2))/C9) -> 0.00059195952 | L9: =MAX(0,$M$2-3*SQRT(($M$2*(1-$M$2))/C9)) -> 0.0001145309 | M9: =$H$33/$C$33 -> 0.00035324521
A10: 9 | B10: 9 | C10: 51943 | D10: 76 | E10: 1463.1423 | F10: 15 | G10: 9 | H10: =F10+G10 -> 24 | I10: 9 | J10: =H10/C10 -> 0.00046204493 | K10: =$M$2+3*SQRT(($M$2*(1-$M$2))/C10) -> 0.00060059933 | L10: =MAX(0,$M$2-3*SQRT(($M$2*(1-$M$2))/C10)) -> 0.00010589108 | M10: =$H$33/$C$33 -> 0.00035324521
A11: 10 | B11: 10 | C11: 47299 | D11: 63 | E11: 1331.952 | F11: 3 | G11: 13 | H11: =F11+G11 -> 16 | I11: 10 | J11: =H11/C11 -> 0.00033827354 | K11: =$M$2+3*SQRT(($M$2*(1-$M$2))/C11) -> 0.00061245816 | L11: =MAX(0,$M$2-3*SQRT(($M$2*(1-$M$2))/C11)) -> 9.4032258e-05 | M11: =$H$33/$C$33 -> 0.00035324521
A12: 11 | B12: 11 | C12: 51710 | D12: 184 | E12: 3558.3059 | F12: 14 | G12: 2 | H12: =F12+G12 -> 16 | I12: 11 | J12: =H12/C12 -> 0.00030941791 | K12: =$M$2+3*SQRT(($M$2*(1-$M$2))/C12) -> 0.00060115598 | L12: =MAX(0,$M$2-3*SQRT(($M$2*(1-$M$2))/C12)) -> 0.00010533443 | M12: =$H$33/$C$33 -> 0.00035324521
A13: 12 | B13: 12 | C13: 56183 | D13: 112 | E13: 1993.4856 | F13: 26 | G13: 2 | H13: =F13+G13 -> 28 | I13: 12 | J13: =H13/C13 -> 0.00049837139 | K13: =$M$2+3*SQRT(($M$2*(1-$M$2))/C13) -> 0.00059108264 | L13: =MAX(0,$M$2-3*SQRT(($M$2*(1-$M$2))/C13)) -> 0.00011540777 | M13: =$H$33/$C$33 -> 0.00035324521
... A25: 24 | B25: 24 | C25: 58398 | D25: 57 | E25: 976.06082 | F25: 1 | G25: 8 | H25: =F25+G25 -> 9 | I25: 24 | J25: =H25/C25 -> 0.00015411487 | K25: =$M$2+3*SQRT(($M$2*(1-$M$2))/C25) -> 0.00058652853 | L25: =MAX(0,$M$2-3*SQRT(($M$2*(1-$M$2))/C25)) -> 0.00011996189 | M25: =$H$33/$C$33 -> 0.00035324521
A26: 25 | B26: 25 | C26: 59244 | D26: 78 | E26: 1316.589 | F26: 5 | G26: 8 | H26: =F26+G26 -> 13 | I26: 25 | J26: =H26/C26 -> 0.0002194315 | K26: =$M$2+3*SQRT(($M$2*(1-$M$2))/C26) -> 0.0005848569 | L26: =MAX(0,$M$2-3*SQRT(($M$2*(1-$M$2))/C26)) -> 0.00012163351 | M26: =$H$33/$C$33 -> 0.00035324521 | R26: P-BAR | S26: =H33/C33 -> 0.00035324521
A27: 26 | B27: 26 | C27: 66897 | D27: 35 | E27: 523.19237 | F27: 3 | G27: 9 | H27: =F27+G27 -> 12 | I27: 26 | J27: =H27/C27 -> 0.00017938024 | K27: =$M$2+3*SQRT(($M$2*(1-$M$2))/C27) -> 0.00057120649 | L27: =MAX(0,$M$2-3*SQRT(($M$2*(1-$M$2))/C27)) -> 0.00013528393 | M27: =$H$33/$C$33 -> 0.00035324521
A28: 27 | B28: 27 | C28: 59013 | D28: 52 | E28: 881.16178 | F28: 0 | G28: 10 | H28: =F28+G28 -> 10 | I28: 27 | J28: =H28/C28 -> 0.00016945419 | K28: =$M$2+3*SQRT(($M$2*(1-$M$2))/C28) -> 0.00058530977 | L28: =MAX(0,$M$2-3*SQRT(($M$2*(1-$M$2))/C28)) -> 0.00012118064 | M28: =$H$33/$C$33 -> 0.00035324521 | R28: LCL
A29: 28 | B29: 28 | C29: 59272 | D29: 35 | E29: 590.49804 | F29: 6 | G29: 5 | H29: =F29+G29 -> 11 | I29: 28 | J29: =H29/C29 -> 0.0001855851 | K29: =$M$2+3*SQRT(($M$2*(1-$M$2))/C29) -> 0.00058480219 | L29: =MAX(0,$M$2-3*SQRT(($M$2*(1-$M$2))/C29)) -> 0.00012168822 | M29: =$H$33/$C$33 -> 0.00035324521
A30: 29 | B30: 29 | C30: 59950 | D30: 52 | E30: 867.38949 | F30: 8 | G30: 7 | H30: =F30+G30 -> 15 | I30: 29 | J30: =H30/C30 -> 0.00025020851 | K30: =$M$2+3*SQRT(($M$2*(1-$M$2))/C30) -> 0.00058348908 | L30: =MAX(0,$M$2-3*SQRT(($M$2*(1-$M$2))/C30)) -> 0.00012300134 | M30: =$H$33/$C$33 -> 0.00035324521
A31: 30 | B31: 30 | C31: 58496 | D31: 105 | E31: 1794.9945 | F31: 0 | G31: 19 | H31: =F31+G31 -> 19 | I31: 30 | J31: =H31/C31 -> 0.00032480853 | K31: =$M$2+3*SQRT(($M$2*(1-$M$2))/C31) -> 0.00058633303 | L31: =MAX(0,$M$2-3*SQRT(($M$2*(1-$M$2))/C31)) -> 0.00012015738 | M31: =$H$33/$C$33 -> 0.00035324521
A32: 31 | B32: 31 | C32: 34689 | D32: 36 | E32: 1037.793 | F32: 0 | G32: 4 | H32: =F32+G32 -> 4 | I32: 31 | J32: =H32/C32 -> 0.00011531033 | K32: =$M$2+3*SQRT(($M$2*(1-$M$2))/C32) -> 0.00065592734 | L32: =MAX(0,$M$2-3*SQRT(($M$2*(1-$M$2))/C32)) -> 5.0563076e-05 | M32: =$H$33/$C$33 -> 0.00035324521
A33: Total | C33: 1721184 | D33: 2785 | E33: 1618.0722 | F33: 300 | G33: 308 | H33: =F33+G33 -> 608 | J33: =H33/C33 -> 0.00035324521 | K33: =$M$2+3*SQRT(($M$2*(1-$M$2))/C33) -> 0.00039621557 | L33: =MAX(0,$M$2-3*SQRT(($M$2*(1-$M$2))/C33)) -> 0.00031027484
R34: UCL

Sheet PARETO
A1: Monthly Rejection Data May. '2026
A2: S NO | B2: DATE | C2: Total Inspection | D2: REJECTION | E2: PPM | F2: Crack | G2: Flange Short | H2: Misfeed | I2: Wrinkle | J2: Damage | K2: Dent / Scratch | L2: Overlap | M2: Bending NG | N2: Flange bend | O2: Hole Oversize | P2: Hole Miss | Q2: HOLE VARIANT NG | R2: Op. miss | S2: Scrap Mark | T2: SHOCK LINE | U2: HOLE OUT | V2: FLANGE CRACK | W2: FLARING NG | X2: Rusty | Y2: FLANGE EXCESS | Z2: Raw Material | AA2: Tool Trial | AB2: Customer Return | AC2: Setting | AD2: Others | AG2: Old rej
A3: 1 | B3: 1 | C3: ='1'!F254 -> 51245 | D3: ='1'!G254 -> 90 | E3: =D3/C3*1000000 -> 1756.2689 | F3: ='1'!I254 -> 0 | G3: ='1'!J254 -> 6 | H3: ='1'!K254 -> 16 | I3: ='1'!L254 -> 1 | J3: ='1'!M254 -> 0 | K3: ='1'!N254 -> 0 | L3: ='1'!O254 -> 8 | M3: ='1'!P254 -> 0 | ... AG3: ='1'!AJ254 -> 0
A4: 2 | B4: 2 | C4: ='2'!F254 -> 53413 | D4: ='2'!G254 -> 95 | E4: =D4/C4*1000000 -> 1778.5932 | F4: ='2'!I254 -> 2 | G4: ='2'!J254 -> 43 | H4: ='2'!K254 -> 29 | I4: ='2'!L254 -> 1 | J4: ='2'!M254 -> 1 | K4: ='2'!N254 -> 10 | L4: ='2'!O254 -> 0 | M4: ='2'!P254 -> 0 | ... AG4: ='2'!AJ254 -> 0
A5: 3 | B5: 3 | C5: =' (3)'!F254 -> 37642 | D5: =' (3)'!G254 -> 88 | E5: =D5/C5*1000000 -> 2337.8141 | F5: =' (3)'!I254 -> 12 | G5: =' (3)'!J254 -> 1 | H5: =' (3)'!K254 -> 24 | I5: =' (3)'!L254 -> 7 | J5: =' (3)'!M254 -> 5 | K5: =' (3)'!N254 -> 10 | L5: =' (3)'!O254 -> 0 | M5: =' (3)'!P254 -> 0 | ... AG5: =' (3)'!AJ254 -> 0
A6: 4 | B6: 4 | C6: =' (4)'!F254 -> 54309 | D6: =' (4)'!G254 -> 85 | E6: =D6/C6*1000000 -> 1565.1181 | F6: =' (4)'!I254 -> 10 | G6: =' (4)'!J254 -> 15 | H6: =' (4)'!K254 -> 24 | I6: =' (4)'!L254 -> 6 | J6: =' (4)'!M254 -> 0 | K6: =' (4)'!N254 -> 16 | L6: =' (4)'!O254 -> 1 | M6: =' (4)'!P254 -> 0 | ... AG6: =' (4)'!AJ254 -> 0
A7: 5 | B7: 5 | C7: =' (5)'!F254 -> 57829 | D7: =' (5)'!G254 -> 142 | E7: =D7/C7*1000000 -> 2455.5154 | F7: =' (5)'!I254 -> 30 | G7: =' (5)'!J254 -> 24 | H7: =' (5)'!K254 -> 14 | I7: =' (5)'!L254 -> 15 | J7: =' (5)'!M254 -> 0 | K7: =' (5)'!N254 -> 5 | L7: =' (5)'!O254 -> 0 | M7: =' (5)'!P254 -> 0 | ... AG7: =' (5)'!AJ254 -> 0
A8: 6 | B8: 6 | C8: =' (6)'!F254 -> 61375 | D8: =' (6)'!G254 -> 50 | E8: =D8/C8*1000000 -> 814.66395 | F8: =' (6)'!I254 -> 9 | G8: =' (6)'!J254 -> 11 | H8: =' (6)'!K254 -> 17 | I8: =' (6)'!L254 -> 1 | J8: =' (6)'!M254 -> 6 | K8: =' (6)'!N254 -> 0 | L8: =' (6)'!O254 -> 0 | M8: =' (6)'!P254 -> 0 | ... AG8: =' (6)'!AJ254 -> 0
A9: 7 | B9: 7 | C9: =' (7)'!F254 -> 58311 | D9: =' (7)'!G254 -> 173 | E9: =D9/C9*1000000 -> 2966.8502 | F9: =' (7)'!I254 -> 5 | G9: =' (7)'!J254 -> 8 | H9: =' (7)'!K254 -> 71 | I9: =' (7)'!L254 -> 0 | J9: =' (7)'!M254 -> 10 | K9: =' (7)'!N254 -> 0 | L9: =' (7)'!O254 -> 0 | M9: =' (7)'!P254 -> 0 | ... AG9: =' (7)'!AJ254 -> 0
A10: 8 | B10: 8 | C10: ='(8)'!F254 -> 55771 | D10: ='(8)'!G254 -> 80 | E10: =D10/C10*1000000 -> 1434.4373 | F10: ='(8)'!I254 -> 2 | G10: ='(8)'!J254 -> 11 | H10: ='(8)'!K254 -> 16 | I10: ='(8)'!L254 -> 0 | J10: ='(8)'!M254 -> 8 | K10: ='(8)'!N254 -> 0 | L10: ='(8)'!O254 -> 21 | M10: ='(8)'!P254 -> 0 | ... AG10: ='(8)'!AJ254 -> 0
A11: 9 | B11: 9 | C11: =' (9)'!F254 -> 51943 | D11: =' (9)'!G254 -> 76 | E11: =D11/C11*1000000 -> 1463.1423 | F11: =' (9)'!I254 -> 15 | G11: =' (9)'!J254 -> 9 | H11: =' (9)'!K254 -> 32 | I11: =' (9)'!L254 -> 6 | J11: =' (9)'!M254 -> 1 | K11: =' (9)'!N254 -> 5 | L11: =' (9)'!O254 -> 0 | M11: =' (9)'!P254 -> 0 | ... AG11: =' (9)'!AJ254 -> 0
A12: 10 | B12: 10 | C12: =' (10)'!F254 -> 47299 | D12: =' (10)'!G254 -> 63 | E12: =D12/C12*1000000 -> 1331.952 | F12: =' (10)'!I254 -> 3 | G12: =' (10)'!J254 -> 13 | H12: =' (10)'!K254 -> 21 | I12: =' (10)'!L254 -> 12 | J12: =' (10)'!M254 -> 0 | K12: =' (10)'!N254 -> 8 | L12: =' (10)'!O254 -> 0 | M12: =' (10)'!P254 -> 0 | ... AG12: =' (10)'!AJ254 -> 0
A13: 11 | B13: 11 | C13: =' (11)'!F254 -> 51710 | D13: =' (11)'!G254 -> 184 | E13: =D13/C13*1000000 -> 3558.3059 | F13: =' (11)'!I254 -> 14 | G13: =' (11)'!J254 -> 2 | H13: =' (11)'!K254 -> 155 | I13: =' (11)'!L254 -> 9 | J13: =' (11)'!M254 -> 0 | K13: =' (11)'!N254 -> 1 | L13: =' (11)'!O254 -> 0 | M13: =' (11)'!P254 -> 0 | ... AG13: =' (11)'!AJ254 -> 0
A14: 12 | B14: 12 | C14: =' (12)'!F254 -> 56183 | D14: =' (12)'!G254 -> 112 | E14: =D14/C14*1000000 -> 1993.4856 | F14: =' (12)'!I254 -> 26 | G14: =' (12)'!J254 -> 2 | H14: =' (12)'!K254 -> 19 | I14: =' (12)'!L254 -> 1 | J14: =' (12)'!M254 -> 0 | K14: =' (12)'!N254 -> 5 | L14: =' (12)'!O254 -> 0 | M14: =' (12)'!P254 -> 0 | ... AG14: =' (12)'!AJ254 -> 0
A15: 13 | B15: 13 | C15: ='(13)'!F254 -> 55317 | D15: ='(13)'!G254 -> 163 | E15: =D15/C15*1000000 -> 2946.6529 | F15: ='(13)'!I254 -> 37 | G15: ='(13)'!J254 -> 11 | H15: ='(13)'!K254 -> 27 | I15: ='(13)'!L254 -> 2 | J15: ='(13)'!M254 -> 0 | K15: ='(13)'!N254 -> 13 | L15: ='(13)'!O254 -> 0 | M15: ='(13)'!P254 -> 0 | ... AG15: ='(13)'!AJ254 -> 0
A16: 14 | B16: 14 | C16: ='(14)'!F254 -> 59237 | D16: ='(14)'!G254 -> 82 | E16: =D16/C16*1000000 -> 1384.27 | F16: ='(14)'!I254 -> 6 | G16: ='(14)'!J254 -> 8 | H16: ='(14)'!K254 -> 50 | I16: ='(14)'!L254 -> 0 | J16: ='(14)'!M254 -> 0 | K16: ='(14)'!N254 -> 1 | L16: ='(14)'!O254 -> 0 | M16: ='(14)'!P254 -> 0 | ... AG16: ='(14)'!AJ254 -> 0
A17: 15 | B17: 15 | C17: ='(15)'!F254 -> 58909 | D17: ='(15)'!G254 -> 102 | E17: =D17/C17*1000000 -> 1731.4842 | F17: ='(15)'!I254 -> 51 | G17: ='(15)'!J254 -> 10 | H17: ='(15)'!K254 -> 18 | I17: ='(15)'!L254 -> 0 | J17: ='(15)'!M254 -> 0 | K17: ='(15)'!N254 -> 0 | L17: ='(15)'!O254 -> 10 | M17: ='(15)'!P254 -> 0 | ... AG17: ='(15)'!AJ254 -> 0
A18: 16 | B18: 16 | C18: ='(16)'!F254 -> 55522 | D18: ='(16)'!G254 -> 89 | E18: =D18/C18*1000000 -> 1602.9682 | F18: ='(16)'!I254 -> 4 | G18: ='(16)'!J254 -> 6 | H18: ='(16)'!K254 -> 46 | I18: ='(16)'!L254 -> 0 | J18: ='(16)'!M254 -> 1 | K18: ='(16)'!N254 -> 12 | L18: ='(16)'!O254 -> 2 | M18: ='(16)'!P254 -> 0 | ... AG18: ='(16)'!AJ254 -> 0
A19: 17 | B19: 17 | C19: ='(17)'!F254 -> 41607 | D19: ='(17)'!G254 -> 106 | E19: =D19/C19*1000000 -> 2547.6482 | F19: ='(17)'!I254 -> 26 | G19: ='(17)'!J254 -> 5 | H19: ='(17)'!K254 -> 32 | I19: ='(17)'!L254 -> 0 | J19: ='(17)'!M254 -> 2 | K19: ='(17)'!N254 -> 13 | L19: ='(17)'!O254 -> 0 | M19: ='(17)'!P254 -> 0 | ... AG19: ='(17)'!AJ254 -> 0
A20: 18 | B20: 18 | C20: ='(18)'!F254 -> 53991 | D20: ='(18)'!G254 -> 70 | E20: =D20/C20*1000000 -> 1296.5124 | F20: ='(18)'!I254 -> 3 | G20: ='(18)'!J254 -> 9 | H20: ='(18)'!K254 -> 25 | I20: ='(18)'!L254 -> 7 | J20: ='(18)'!M254 -> 14 | K20: ='(18)'!N254 -> 0 | L20: ='(18)'!O254 -> 2 | M20: ='(18)'!P254 -> 0 | ... AG20: ='(18)'!AJ254 -> 0
A21: 19 | B21: 19 | C21: ='19'!F254 -> 65142 | D21: ='19'!G254 -> 76 | E21: =D21/C21*1000000 -> 1166.682 | F21: ='19'!I254 -> 13 | G21: ='19'!J254 -> 9 | H21: ='19'!K254 -> 11 | I21: ='19'!L254 -> 17 | J21: ='19'!M254 -> 12 | K21: ='19'!N254 -> 0 | L21: ='19'!O254 -> 0 | M21: ='19'!P254 -> 0 | ... AG21: ='19'!AJ254 -> 0
A22: 20 | B22: 20 | C22: =' (20)'!F254 -> 59421 | D22: =' (20)'!G254 -> 103 | E22: =D22/C22*1000000 -> 1733.3939 | F22: =' (20)'!I254 -> 0 | G22: =' (20)'!J254 -> 9 | H22: =' (20)'!K254 -> 20 | I22: =' (20)'!L254 -> 2 | J22: =' (20)'!M254 -> 11 | K22: =' (20)'!N254 -> 5 | L22: =' (20)'!O254 -> 0 | M22: =' (20)'!P254 -> 0 | ... AG22: =' (20)'!AJ254 -> 0
A23: 21 | B23: 21 | C23: =' (21)'!F254 -> 58885 | D23: =' (21)'!G254 -> 76 | E23: =D23/C23*1000000 -> 1290.6513 | F23: =' (21)'!I254 -> 4 | G23: =' (21)'!J254 -> 15 | H23: =' (21)'!K254 -> 22 | I23: =' (21)'!L254 -> 0 | J23: =' (21)'!M254 -> 6 | K23: =' (21)'!N254 -> 13 | L23: =' (21)'!O254 -> 0 | M23: =' (21)'!P254 -> 0 | ... AG23: =' (21)'!AJ254 -> 0
A24: 22 | B24: 22 | C24: =' (22)'!F254 -> 60268 | D24: =' (22)'!G254 -> 133 | E24: =D24/C24*1000000 -> 2206.8096 | F24: =' (22)'!I254 -> 3 | G24: =' (22)'!J254 -> 9 | H24: =' (22)'!K254 -> 43 | I24: =' (22)'!L254 -> 0 | J24: =' (22)'!M254 -> 5 | K24: =' (22)'!N254 -> 12 | L24: =' (22)'!O254 -> 2 | M24: =' (22)'!P254 -> 0 | ... AG24: =' (22)'!AJ254 -> 0
A25: 23 | B25: 23 | C25: =' (23)'!F254 -> 59896 | D25: =' (23)'!G254 -> 97 | E25: =D25/C25*1000000 -> 1619.4738 | F25: =' (23)'!I254 -> 2 | G25: =' (23)'!J254 -> 2 | H25: =' (23)'!K254 -> 36 | I25: =' (23)'!L254 -> 0 | J25: =' (23)'!M254 -> 7 | K25: =' (23)'!N254 -> 12 | L25: =' (23)'!O254 -> 10 | M25: =' (23)'!P254 -> 0 | ... AG25: =' (23)'!AJ254 -> 0
A26: 24 | B26: 24 | C26: =' (24)'!F254 -> 58398 | D26: =' (24)'!G254 -> 57 | E26: =D26/C26*1000000 -> 976.06082 | F26: =' (24)'!I254 -> 1 | G26: =' (24)'!J254 -> 8 | H26: =' (24)'!K254 -> 9 | I26: =' (24)'!L254 -> 1 | J26: =' (24)'!M254 -> 0 | K26: =' (24)'!N254 -> 14 | L26: =' (24)'!O254 -> 0 | M26: =' (24)'!P254 -> 0 | ... AG26: =' (24)'!AJ254 -> 0
A27: 25 | B27: 25 | C27: =' (25)'!F254 -> 59244 | D27: =' (25)'!G254 -> 78 | E27: =D27/C27*1000000 -> 1316.589 | F27: =' (25)'!I254 -> 5 | G27: =' (25)'!J254 -> 8 | H27: =' (25)'!K254 -> 11 | I27: =' (25)'!L254 -> 0 | J27: =' (25)'!M254 -> 0 | K27: =' (25)'!N254 -> 4 | L27: =' (25)'!O254 -> 12 | M27: =' (25)'!P254 -> 0 | ... AG27: =' (25)'!AJ254 -> 0
A28: 26 | B28: 26 | C28: =' (26)'!F254 -> 66897 | D28: =' (26)'!G254 -> 35 | E28: =D28/C28*1000000 -> 523.19237 | F28: =' (26)'!I254 -> 3 | G28: =' (26)'!J254 -> 9 | H28: =' (26)'!K254 -> 15 | I28: =' (26)'!L254 -> 0 | J28: =' (26)'!M254 -> 0 | K28: =' (26)'!N254 -> 0 | L28: =' (26)'!O254 -> 0 | M28: =' (26)'!P254 -> 0 | ... AG28: =' (26)'!AJ254 -> 0
A29: 27 | B29: 27 | C29: =' (27)'!F254 -> 59013 | D29: =' (27)'!G254 -> 52 | E29: =D29/C29*1000000 -> 881.16178 | F29: =' (27)'!I254 -> 0 | G29: =' (27)'!J254 -> 10 | H29: =' (27)'!K254 -> 16 | I29: =' (27)'!L254 -> 4 | J29: =' (27)'!M254 -> 0 | K29: =' (27)'!N254 -> 10 | L29: =' (27)'!O254 -> 0 | M29: =' (27)'!P254 -> 0 | ... AG29: =' (27)'!AJ254 -> 0
A30: 28 | B30: 28 | C30: ='(28)'!F254 -> 59272 | D30: ='(28)'!G254 -> 35 | E30: =D30/C30*1000000 -> 590.49804 | F30: ='(28)'!I254 -> 6 | G30: ='(28)'!J254 -> 5 | H30: ='(28)'!K254 -> 5 | I30: ='(28)'!L254 -> 0 | J30: ='(28)'!M254 -> 6 | K30: ='(28)'!N254 -> 0 | L30: ='(28)'!O254 -> 0 | M30: ='(28)'!P254 -> 0 | ... AG30: ='(28)'!AJ254 -> 0
A31: 29 | B31: 29 | C31: =' (29)'!F254 -> 59950 | D31: =' (29)'!G254 -> 52 | E31: =D31/C31*1000000 -> 867.38949 | F31: =' (29)'!I254 -> 8 | G31: =' (29)'!J254 -> 7 | H31: =' (29)'!K254 -> 9 | I31: =' (29)'!L254 -> 0 | J31: =' (29)'!M254 -> 17 | K31: =' (29)'!N254 -> 0 | L31: =' (29)'!O254 -> 4 | M31: =' (29)'!P254 -> 0 | ... AG31: =' (29)'!AJ254 -> 0
A32: 30 | B32: 30 | C32: =' (30)'!F254 -> 58496 | D32: =' (30)'!G254 -> 105 | E32: =D32/C32*1000000 -> 1794.9945 | F32: =' (30)'!I254 -> 0 | G32: =' (30)'!J254 -> 19 | H32: =' (30)'!K254 -> 15 | I32: =' (30)'!L254 -> 3 | J32: =' (30)'!M254 -> 0 | K32: =' (30)'!N254 -> 0 | L32: =' (30)'!O254 -> 4 | M32: =' (30)'!P254 -> 0 | ... AG32: =' (30)'!AJ254 -> 0
A33: 31 | B33: 31 | C33: ='(31)'!F254 -> 34689 | D33: ='(31)'!G254 -> 36 | E33: =D33/C33*1000000 -> 1037.793 | F33: ='(31)'!I254 -> 0 | G33: ='(31)'!J254 -> 4 | H33: ='(31)'!K254 -> 11 | I33: ='(31)'!L254 -> 3 | J33: ='(31)'!M254 -> 4 | K33: ='(31)'!N254 -> 0 | L33: ='(31)'!O254 -> 0 | M33: ='(31)'!P254 -> 0 | ... AG33: ='(31)'!AJ254 -> 0
A34: Total | C34: =SUM(C3:C33) -> 1721184 | D34: =SUM(D3:D33) -> 2785 | E34: =D34/C34*1000000 -> 1618.0722 | F34: =SUM(F3:F33) -> 300 | G34: =SUM(G3:G33) -> 308 | H34: =SUM(H3:H33) -> 859 | I34: =SUM(I3:I33) -> 98 | J34: =SUM(J3:J33) -> 116 | K34: =SUM(K3:K33) -> 169 | L34: =SUM(L3:L33) -> 76 | M34: =SUM(M3:M33) -> 0 | ... AG34: =SUM(AG3:AG33) -> 0
C36: =D34/C34 -> 0.0016180722
B37: Baseline Sigma Total | C37: =_xlfn.NORM.S.INV(1-C36)+1.5 -> 4.4443685
C39: =E34/1000000 -> 0.0016180722
C40: =1-C39 -> 0.99838193
C43: According to yield to Sigma Conversion | D43: 4.42
C44: Base Line Sigma Through PPM | D44: 4.5
...

Sheet TOTAL (2)
A1: Monthly Rejection Data May. '2026
A2: S NO | B2: DATE | C2: Total Inspection | D2: REJECTION | E2: PPM | F2: Crack | G2: Flange Short | H2: Misfeed | I2: Wrinkle | J2: Damage | K2: Dent / Scratch | L2: Overlap | M2: Bending NG | N2: Flange bend | O2: Hole Oversize | P2: Hole Miss | Q2: HOLE VARIANT NG | R2: Op. miss | S2: Scrap Mark | T2: SHOCK LINE | U2: HOLE OUT | V2: FLANGE CRACK | W2: FLARING NG | X2: Rusty | Y2: FLANGE EXCESS | Z2: Raw Material | AA2: Tool Trial | AB2: Customer Return | AC2: Setting | AD2: Others | AG2: Old rej
A3: 1 | B3: 1 | C3: ='1'!F254 -> 51245 | D3: ='1'!G254 -> 90 | E3: =D3/C3*1000000 -> 1756.2689 | F3: ='1'!I254 -> 0 | G3: ='1'!J254 -> 6 | H3: ='1'!K254 -> 16 | I3: ='1'!L254 -> 1 | J3: ='1'!M254 -> 0 | K3: ='1'!N254 -> 0 | L3: ='1'!O254 -> 8 | M3: ='1'!P254 -> 0 | ... AG3: ='1'!AJ254 -> 0
A4: 2 | B4: 2 | C4: ='2'!F254 -> 53413 | D4: ='2'!G254 -> 95 | E4: =D4/C4*1000000 -> 1778.5932 | F4: ='2'!I254 -> 2 | G4: ='2'!J254 -> 43 | H4: ='2'!K254 -> 29 | I4: ='2'!L254 -> 1 | J4: ='2'!M254 -> 1 | K4: ='2'!N254 -> 10 | L4: ='2'!O254 -> 0 | M4: ='2'!P254 -> 0 | ... AG4: ='2'!AJ254 -> 0
A5: 3 | B5: 3 | C5: =' (3)'!F254 -> 37642 | D5: =' (3)'!G254 -> 88 | E5: =D5/C5*1000000 -> 2337.8141 | F5: =' (3)'!I254 -> 12 | G5: =' (3)'!J254 -> 1 | H5: =' (3)'!K254 -> 24 | I5: =' (3)'!L254 -> 7 | J5: =' (3)'!M254 -> 5 | K5: =' (3)'!N254 -> 10 | L5: =' (3)'!O254 -> 0 | M5: =' (3)'!P254 -> 0 | ... AG5: =' (3)'!AJ254 -> 0
A6: 4 | B6: 4 | C6: =' (4)'!F254 -> 54309 | D6: =' (4)'!G254 -> 85 | E6: =D6/C6*1000000 -> 1565.1181 | F6: =' (4)'!I254 -> 10 | G6: =' (4)'!J254 -> 15 | H6: =' (4)'!K254 -> 24 | I6: =' (4)'!L254 -> 6 | J6: =' (4)'!M254 -> 0 | K6: =' (4)'!N254 -> 16 | L6: =' (4)'!O254 -> 1 | M6: =' (4)'!P254 -> 0 | ... AG6: =' (4)'!AJ254 -> 0
A7: 5 | B7: 5 | C7: =' (5)'!F254 -> 57829 | D7: =' (5)'!G254 -> 142 | E7: =D7/C7*1000000 -> 2455.5154 | F7: =' (5)'!I254 -> 30 | G7: =' (5)'!J254 -> 24 | H7: =' (5)'!K254 -> 14 | I7: =' (5)'!L254 -> 15 | J7: =' (5)'!M254 -> 0 | K7: =' (5)'!N254 -> 5 | L7: =' (5)'!O254 -> 0 | M7: =' (5)'!P254 -> 0 | ... AG7: =' (5)'!AJ254 -> 0
A8: 6 | B8: 6 | C8: =' (6)'!F254 -> 61375 | D8: =' (6)'!G254 -> 50 | E8: =D8/C8*1000000 -> 814.66395 | F8: =' (6)'!I254 -> 9 | G8: =' (6)'!J254 -> 11 | H8: =' (6)'!K254 -> 17 | I8: =' (6)'!L254 -> 1 | J8: =' (6)'!M254 -> 6 | K8: =' (6)'!N254 -> 0 | L8: =' (6)'!O254 -> 0 | M8: =' (6)'!P254 -> 0 | ... AG8: =' (6)'!AJ254 -> 0
A9: 7 | B9: 7 | C9: =' (7)'!F254 -> 58311 | D9: =' (7)'!G254 -> 173 | E9: =D9/C9*1000000 -> 2966.8502 | F9: =' (7)'!I254 -> 5 | G9: =' (7)'!J254 -> 8 | H9: =' (7)'!K254 -> 71 | I9: =' (7)'!L254 -> 0 | J9: =' (7)'!M254 -> 10 | K9: =' (7)'!N254 -> 0 | L9: =' (7)'!O254 -> 0 | M9: =' (7)'!P254 -> 0 | ... AG9: =' (7)'!AJ254 -> 0
A10: 8 | B10: 8 | C10: ='(8)'!F254 -> 55771 | D10: ='(8)'!G254 -> 80 | E10: =D10/C10*1000000 -> 1434.4373 | F10: ='(8)'!I254 -> 2 | G10: ='(8)'!J254 -> 11 | H10: ='(8)'!K254 -> 16 | I10: ='(8)'!L254 -> 0 | J10: ='(8)'!M254 -> 8 | K10: ='(8)'!N254 -> 0 | L10: ='(8)'!O254 -> 21 | M10: ='(8)'!P254 -> 0 | ... AG10: ='(8)'!AJ254 -> 0
A11: 9 | B11: 9 | C11: =' (9)'!F254 -> 51943 | D11: =' (9)'!G254 -> 76 | E11: =D11/C11*1000000 -> 1463.1423 | F11: =' (9)'!I254 -> 15 | G11: =' (9)'!J254 -> 9 | H11: =' (9)'!K254 -> 32 | I11: =' (9)'!L254 -> 6 | J11: =' (9)'!M254 -> 1 | K11: =' (9)'!N254 -> 5 | L11: =' (9)'!O254 -> 0 | M11: =' (9)'!P254 -> 0 | ... AG11: =' (9)'!AJ254 -> 0
A12: 10 | B12: 10 | C12: =' (10)'!F254 -> 47299 | D12: =' (10)'!G254 -> 63 | E12: =D12/C12*1000000 -> 1331.952 | F12: =' (10)'!I254 -> 3 | G12: =' (10)'!J254 -> 13 | H12: =' (10)'!K254 -> 21 | I12: =' (10)'!L254 -> 12 | J12: =' (10)'!M254 -> 0 | K12: =' (10)'!N254 -> 8 | L12: =' (10)'!O254 -> 0 | M12: =' (10)'!P254 -> 0 | ... AG12: =' (10)'!AJ254 -> 0
A13: 11 | B13: 11 | C13: =' (11)'!F254 -> 51710 | D13: =' (11)'!G254 -> 184 | E13: =D13/C13*1000000 -> 3558.3059 | F13: =' (11)'!I254 -> 14 | G13: =' (11)'!J254 -> 2 | H13: =' (11)'!K254 -> 155 | I13: =' (11)'!L254 -> 9 | J13: =' (11)'!M254 -> 0 | K13: =' (11)'!N254 -> 1 | L13: =' (11)'!O254 -> 0 | M13: =' (11)'!P254 -> 0 | ... AG13: =' (11)'!AJ254 -> 0
A14: 12 | B14: 12 | C14: =' (12)'!F254 -> 56183 | D14: =' (12)'!G254 -> 112 | E14: =D14/C14*1000000 -> 1993.4856 | F14: =' (12)'!I254 -> 26 | G14: =' (12)'!J254 -> 2 | H14: =' (12)'!K254 -> 19 | I14: =' (12)'!L254 -> 1 | J14: =' (12)'!M254 -> 0 | K14: =' (12)'!N254 -> 5 | L14: =' (12)'!O254 -> 0 | M14: =' (12)'!P254 -> 0 | ... AG14: =' (12)'!AJ254 -> 0
A15: 13 | B15: 13 | C15: ='(13)'!F254 -> 55317 | D15: ='(13)'!G254 -> 163 | E15: =D15/C15*1000000 -> 2946.6529 | F15: ='(13)'!I254 -> 37 | G15: ='(13)'!J254 -> 11 | H15: ='(13)'!K254 -> 27 | I15: ='(13)'!L254 -> 2 | J15: ='(13)'!M254 -> 0 | K15: ='(13)'!N254 -> 13 | L15: ='(13)'!O254 -> 0 | M15: ='(13)'!P254 -> 0 | ... AG15: ='(13)'!AJ254 -> 0
A16: 14 | B16: 14 | C16: ='(14)'!F254 -> 59237 | D16: ='(14)'!G254 -> 82 | E16: =D16/C16*1000000 -> 1384.27 | F16: ='(14)'!I254 -> 6 | G16: ='(14)'!J254 -> 8 | H16: ='(14)'!K254 -> 50 | I16: ='(14)'!L254 -> 0 | J16: ='(14)'!M254 -> 0 | K16: ='(14)'!N254 -> 1 | L16: ='(14)'!O254 -> 0 | M16: ='(14)'!P254 -> 0 | ... AG16: ='(14)'!AJ254 -> 0
A17: 15 | B17: 15 | C17: ='(15)'!F254 -> 58909 | D17: ='(15)'!G254 -> 102 | E17: =D17/C17*1000000 -> 1731.4842 | F17: ='(15)'!I254 -> 51 | G17: ='(15)'!J254 -> 10 | H17: ='(15)'!K254 -> 18 | I17: ='(15)'!L254 -> 0 | J17: ='(15)'!M254 -> 0 | K17: ='(15)'!N254 -> 0 | L17: ='(15)'!O254 -> 10 | M17: ='(15)'!P254 -> 0 | ... AG17: ='(15)'!AJ254 -> 0
A18: 16 | B18: 16 | C18: ='(16)'!F254 -> 55522 | D18: ='(16)'!G254 -> 89 | E18: =D18/C18*1000000 -> 1602.9682 | F18: ='(16)'!I254 -> 4 | G18: ='(16)'!J254 -> 6 | H18: ='(16)'!K254 -> 46 | I18: ='(16)'!L254 -> 0 | J18: ='(16)'!M254 -> 1 | K18: ='(16)'!N254 -> 12 | L18: ='(16)'!O254 -> 2 | M18: ='(16)'!P254 -> 0 | ... AG18: ='(16)'!AJ254 -> 0
A19: 17 | B19: 17 | C19: ='(17)'!F254 -> 41607 | D19: ='(17)'!G254 -> 106 | E19: =D19/C19*1000000 -> 2547.6482 | F19: ='(17)'!I254 -> 26 | G19: ='(17)'!J254 -> 5 | H19: ='(17)'!K254 -> 32 | I19: ='(17)'!L254 -> 0 | J19: ='(17)'!M254 -> 2 | K19: ='(17)'!N254 -> 13 | L19: ='(17)'!O254 -> 0 | M19: ='(17)'!P254 -> 0 | ... AG19: ='(17)'!AJ254 -> 0
A20: 18 | B20: 18 | C20: ='(18)'!F254 -> 53991 | D20: ='(18)'!G254 -> 70 | E20: =D20/C20*1000000 -> 1296.5124 | F20: ='(18)'!I254 -> 3 | G20: ='(18)'!J254 -> 9 | H20: ='(18)'!K254 -> 25 | I20: ='(18)'!L254 -> 7 | J20: ='(18)'!M254 -> 14 | K20: ='(18)'!N254 -> 0 | L20: ='(18)'!O254 -> 2 | M20: ='(18)'!P254 -> 0 | ... AG20: ='(18)'!AJ254 -> 0
A21: 19 | B21: 19 | C21: ='19'!F254 -> 65142 | D21: ='19'!G254 -> 76 | E21: =D21/C21*1000000 -> 1166.682 | F21: ='19'!I254 -> 13 | G21: ='19'!J254 -> 9 | H21: ='19'!K254 -> 11 | I21: ='19'!L254 -> 17 | J21: ='19'!M254 -> 12 | K21: ='19'!N254 -> 0 | L21: ='19'!O254 -> 0 | M21: ='19'!P254 -> 0 | ... AG21: ='19'!AJ254 -> 0
A22: 20 | B22: 20 | C22: =' (20)'!F254 -> 59421 | D22: =' (20)'!G254 -> 103 | E22: =D22/C22*1000000 -> 1733.3939 | F22: =' (20)'!I254 -> 0 | G22: =' (20)'!J254 -> 9 | H22: =' (20)'!K254 -> 20 | I22: =' (20)'!L254 -> 2 | J22: =' (20)'!M254 -> 11 | K22: =' (20)'!N254 -> 5 | L22: =' (20)'!O254 -> 0 | M22: =' (20)'!P254 -> 0 | ... AG22: =' (20)'!AJ254 -> 0
A23: 21 | B23: 21 | C23: =' (21)'!F254 -> 58885 | D23: =' (21)'!G254 -> 76 | E23: =D23/C23*1000000 -> 1290.6513 | F23: =' (21)'!I254 -> 4 | G23: =' (21)'!J254 -> 15 | H23: =' (21)'!K254 -> 22 | I23: =' (21)'!L254 -> 0 | J23: =' (21)'!M254 -> 6 | K23: =' (21)'!N254 -> 13 | L23: =' (21)'!O254 -> 0 | M23: =' (21)'!P254 -> 0 | ... AG23: =' (21)'!AJ254 -> 0
A24: 22 | B24: 22 | C24: =' (22)'!F254 -> 60268 | D24: =' (22)'!G254 -> 133 | E24: =D24/C24*1000000 -> 2206.8096 | F24: =' (22)'!I254 -> 3 | G24: =' (22)'!J254 -> 9 | H24: =' (22)'!K254 -> 43 | I24: =' (22)'!L254 -> 0 | J24: =' (22)'!M254 -> 5 | K24: =' (22)'!N254 -> 12 | L24: =' (22)'!O254 -> 2 | M24: =' (22)'!P254 -> 0 | ... AG24: =' (22)'!AJ254 -> 0
A25: 23 | B25: 23 | C25: =' (23)'!F254 -> 59896 | D25: =' (23)'!G254 -> 97 | E25: =D25/C25*1000000 -> 1619.4738 | F25: =' (23)'!I254 -> 2 | G25: =' (23)'!J254 -> 2 | H25: =' (23)'!K254 -> 36 | I25: =' (23)'!L254 -> 0 | J25: =' (23)'!M254 -> 7 | K25: =' (23)'!N254 -> 12 | L25: =' (23)'!O254 -> 10 | M25: =' (23)'!P254 -> 0 | ... AG25: =' (23)'!AJ254 -> 0
A26: 24 | B26: 24 | C26: =' (24)'!F254 -> 58398 | D26: =' (24)'!G254 -> 57 | E26: =D26/C26*1000000 -> 976.06082 | F26: =' (24)'!I254 -> 1 | G26: =' (24)'!J254 -> 8 | H26: =' (24)'!K254 -> 9 | I26: =' (24)'!L254 -> 1 | J26: =' (24)'!M254 -> 0 | K26: =' (24)'!N254 -> 14 | L26: =' (24)'!O254 -> 0 | M26: =' (24)'!P254 -> 0 | ... AG26: =' (24)'!AJ254 -> 0
A27: 25 | B27: 25 | C27: =' (25)'!F254 -> 59244 | D27: =' (25)'!G254 -> 78 | E27: =D27/C27*1000000 -> 1316.589 | F27: =' (25)'!I254 -> 5 | G27: =' (25)'!J254 -> 8 | H27: =' (25)'!K254 -> 11 | I27: =' (25)'!L254 -> 0 | J27: =' (25)'!M254 -> 0 | K27: =' (25)'!N254 -> 4 | L27: =' (25)'!O254 -> 12 | M27: =' (25)'!P254 -> 0 | ... AG27: =' (25)'!AJ254 -> 0
A28: 26 | B28: 26 | C28: =' (26)'!F254 -> 66897 | D28: =' (26)'!G254 -> 35 | E28: =D28/C28*1000000 -> 523.19237 | F28: =' (26)'!I254 -> 3 | G28: =' (26)'!J254 -> 9 | H28: =' (26)'!K254 -> 15 | I28: =' (26)'!L254 -> 0 | J28: =' (26)'!M254 -> 0 | K28: =' (26)'!N254 -> 0 | L28: =' (26)'!O254 -> 0 | M28: =' (26)'!P254 -> 0 | ... AG28: =' (26)'!AJ254 -> 0
A29: 27 | B29: 27 | C29: =' (27)'!F254 -> 59013 | D29: =' (27)'!G254 -> 52 | E29: =D29/C29*1000000 -> 881.16178 | F29: =' (27)'!I254 -> 0 | G29: =' (27)'!J254 -> 10 | H29: =' (27)'!K254 -> 16 | I29: =' (27)'!L254 -> 4 | J29: =' (27)'!M254 -> 0 | K29: =' (27)'!N254 -> 10 | L29: =' (27)'!O254 -> 0 | M29: =' (27)'!P254 -> 0 | ... AG29: =' (27)'!AJ254 -> 0
A30: 28 | B30: 28 | C30: ='(28)'!F254 -> 59272 | D30: ='(28)'!G254 -> 35 | E30: =D30/C30*1000000 -> 590.49804 | F30: ='(28)'!I254 -> 6 | G30: ='(28)'!J254 -> 5 | H30: ='(28)'!K254 -> 5 | I30: ='(28)'!L254 -> 0 | J30: ='(28)'!M254 -> 6 | K30: ='(28)'!N254 -> 0 | L30: ='(28)'!O254 -> 0 | M30: ='(28)'!P254 -> 0 | ... AG30: ='(28)'!AJ254 -> 0
A31: 29 | B31: 29 | C31: =' (29)'!F254 -> 59950 | D31: =' (29)'!G254 -> 52 | E31: =D31/C31*1000000 -> 867.38949 | F31: =' (29)'!I254 -> 8 | G31: =' (29)'!J254 -> 7 | H31: =' (29)'!K254 -> 9 | I31: =' (29)'!L254 -> 0 | J31: =' (29)'!M254 -> 17 | K31: =' (29)'!N254 -> 0 | L31: =' (29)'!O254 -> 4 | M31: =' (29)'!P254 -> 0 | ... AG31: =' (29)'!AJ254 -> 0
A32: 30 | B32: 30 | C32: =' (30)'!F254 -> 58496 | D32: =' (30)'!G254 -> 105 | E32: =D32/C32*1000000 -> 1794.9945 | F32: =' (30)'!I254 -> 0 | G32: =' (30)'!J254 -> 19 | H32: =' (30)'!K254 -> 15 | I32: =' (30)'!L254 -> 3 | J32: =' (30)'!M254 -> 0 | K32: =' (30)'!N254 -> 0 | L32: =' (30)'!O254 -> 4 | M32: =' (30)'!P254 -> 0 | ... AG32: =' (30)'!AJ254 -> 0
A33: 31 | B33: 31 | C33: ='(31)'!F254 -> 34689 | D33: ='(31)'!G254 -> 36 | E33: =D33/C33*1000000 -> 1037.793 | F33: ='(31)'!I254 -> 0 | G33: ='(31)'!J254 -> 4 | H33: ='(31)'!K254 -> 11 | I33: ='(31)'!L254 -> 3 | J33: ='(31)'!M254 -> 4 | K33: ='(31)'!N254 -> 0 | L33: ='(31)'!O254 -> 0 | M33: ='(31)'!P254 -> 0 | ... AG33: ='(31)'!AJ254 -> 0
A34: Total | C34: =SUM(C3:C33) -> 1721184 | D34: =SUM(D3:D33) -> 2785 | E34: =D34/C34*1000000 -> 1618.0722 | F34: =SUM(F3:F33) -> 300 | G34: =SUM(G3:G33) -> 308 | H34: =SUM(H3:H33) -> 859 | I34: =SUM(I3:I33) -> 98 | J34: =SUM(J3:J33) -> 116 | K34: =SUM(K3:K33) -> 169 | L34: =SUM(L3:L33) -> 76 | M34: =SUM(M3:M33) -> 0 | ... AG34: =SUM(AG3:AG33) -> 0

Sheet Sheet4

Sheet Sheet5
B2: Misfeed | C2: 391
B3: Setting | C3: 319
B4: Flange Short | C4: 252
B5: Wrinkle | C5: 29
B6: Dent / Scratch | C6: 236
B7: Flange bend | C7: 147
B8: Crack | C8: 97
B9: Others | C9: 97
B10: Damage | C10: 94
B11: FLANGE CRACK | C11: 86
B12: Scrap Mark | C12: 63
B13: Rusty | C13: 20
... B26: Customer Return | C26: 0
C27: 0
C28: 0
C29: 0

Sheet MOdel Wise
A1: Monthly Rejection Data May. '2026
A2: Model | B2: Crack | C2: Flange Short | D2: Misfeed | E2: Wrinkle | F2: Damage | G2: Dent / Scratch | H2: Overlap | I2: Bending NG | J2: Flange bend | K2: Hole Oversize | L2: Hole Miss | M2: HOLE VARIANT NG | N2: Op. miss | O2: Scrap Mark | P2: SHOCK LINE | Q2: HOLE OUT | R2: FLANGE CRACK | S2: FLARING NG | T2: Rusty | U2: FLANGE EXCESS | V2: Raw Material | W2: Tool Trial | X2: Customer Return | Y2: Setting | Z2: Others | AC2: Old rej | AD2: Total
A3: YHC | B3: =SUM(#REF!) -> #REF! | C3: =SUM(#REF!) -> #REF! | D3: =SUM(#REF!) -> #REF! | E3: =SUM(#REF!) -> #REF! | F3: =SUM(#REF!) -> #REF! | G3: =SUM(#REF!) -> #REF! | H3: =SUM(#REF!) -> #REF! | I3: =SUM(#REF!) -> #REF! | ... AC3: =SUM(#REF!) -> #REF! | AD3: =SUM(B3:AC3) -> #REF!
A4: Y1K | B4: =SUM(#REF!) -> #REF! | C4: =SUM(#REF!) -> #REF! | D4: =SUM(#REF!) -> #REF! | E4: =SUM(#REF!) -> #REF! | F4: =SUM(#REF!) -> #REF! | G4: =SUM(#REF!) -> #REF! | H4: =SUM(#REF!) -> #REF! | I4: =SUM(#REF!) -> #REF! | ... AC4: =SUM(#REF!) -> #REF! | AD4: =SUM(B4:AC4) -> #REF!
A5: YCA | B5: =SUM(#REF!,#REF!) -> #REF! | C5: =SUM(#REF!,#REF!) -> #REF! | D5: =SUM(#REF!,#REF!) -> #REF! | E5: =SUM(#REF!,#REF!) -> #REF! | F5: =SUM(#REF!,#REF!) -> #REF! | G5: =SUM(#REF!,#REF!) -> #REF! | H5: =SUM(#REF!,#REF!) -> #REF! | I5: =SUM(#REF!,#REF!) -> #REF! | ... AC5: =SUM(#REF!,#REF!) -> #REF! | AD5: =SUM(B5:AC5) -> #REF!
A6: YG8 | B6: =SUM(#REF!,#REF!,#REF!,#REF!,#REF!,#REF!,#REF!) -> #REF! | C6: =SUM(#REF!,#REF!,#REF!,#REF!,#REF!,#REF!,#REF!) -> #REF! | D6: =SUM(#REF!,#REF!,#REF!,#REF!,#REF!,#REF!,#REF!) -> #REF! | E6: =SUM(#REF!,#REF!,#REF!,#REF!,#REF!,#REF!,#REF!) -> #REF! | F6: =SUM(#REF!,#REF!,#REF!,#REF!,#REF!,#REF!,#REF!) -> #REF! | G6: =SUM(#REF!,#REF!,#REF!,#REF!,#REF!,#REF!,#REF!) -> #REF! | H6: =SUM(#REF!,#REF!,#REF!,#REF!,#REF!,#REF!,#REF!) -> #REF! | I6: =SUM(#REF!,#REF!,#REF!,#REF!,#REF!,#REF!,#REF!) -> #REF! | ... AC6: =SUM(#REF!,#REF!,#REF!,#REF!,#REF!,#REF!,#REF!) -> #REF! | AD6: =SUM(B6:AC6) -> #REF!
A7: B6 | B7: =SUM(#REF!,#REF!,#REF!,#REF!) -> #REF! | C7: =SUM(#REF!,#REF!,#REF!,#REF!) -> #REF! | D7: =SUM(#REF!,#REF!,#REF!,#REF!) -> #REF! | E7: =SUM(#REF!,#REF!,#REF!,#REF!) -> #REF! | F7: =SUM(#REF!,#REF!,#REF!,#REF!) -> #REF! | G7: =SUM(#REF!,#REF!,#REF!,#REF!) -> #REF! | H7: =SUM(#REF!,#REF!,#REF!,#REF!) -> #REF! | I7: =SUM(#REF!,#REF!,#REF!,#REF!) -> #REF! | ... AC7: =SUM(#REF!,#REF!,#REF!,#REF!) -> #REF! | AD7: =SUM(B7:AC7) -> #REF!
A8: YJC | B8: =SUM(#REF!) -> #REF! | C8: =SUM(#REF!) -> #REF! | D8: =SUM(#REF!) -> #REF! | E8: =SUM(#REF!) -> #REF! | F8: =SUM(#REF!) -> #REF! | G8: =SUM(#REF!) -> #REF! | H8: =SUM(#REF!) -> #REF! | I8: =SUM(#REF!) -> #REF! | ... AC8: =SUM(#REF!) -> #REF! | AD8: =SUM(B8:AC8) -> #REF!
A9: RX | B9: =SUM(#REF!) -> #REF! | C9: =SUM(#REF!) -> #REF! | D9: =SUM(#REF!) -> #REF! | E9: =SUM(#REF!) -> #REF! | F9: =SUM(#REF!) -> #REF! | G9: =SUM(#REF!) -> #REF! | H9: =SUM(#REF!) -> #REF! | I9: =SUM(#REF!) -> #REF! | ... AC9: =SUM(#REF!) -> #REF! | AD9: =SUM(B9:AC9) -> #REF!
A10: XD | B10: =SUM(#REF!) -> #REF! | C10: =SUM(#REF!) -> #REF! | D10: =SUM(#REF!) -> #REF! | E10: =SUM(#REF!) -> #REF! | F10: =SUM(#REF!) -> #REF! | G10: =SUM(#REF!) -> #REF! | H10: =SUM(#REF!) -> #REF! | I10: =SUM(#REF!) -> #REF! | ... AC10: =SUM(#REF!) -> #REF! | AD10: =SUM(B10:AC10) -> #REF!
A11: JCB | B11: =SUM(#REF!,#REF!,#REF!,#REF!) -> #REF! | C11: =SUM(#REF!,#REF!,#REF!,#REF!) -> #REF! | D11: =SUM(#REF!,#REF!,#REF!,#REF!) -> #REF! | E11: =SUM(#REF!,#REF!,#REF!,#REF!) -> #REF! | F11: =SUM(#REF!,#REF!,#REF!,#REF!) -> #REF! | G11: =SUM(#REF!,#REF!,#REF!,#REF!) -> #REF! | H11: =SUM(#REF!,#REF!,#REF!,#REF!) -> #REF! | I11: =SUM(#REF!,#REF!,#REF!,#REF!) -> #REF! | ... AC11: =SUM(#REF!,#REF!,#REF!,#REF!) -> #REF! | AD11: =SUM(B11:AC11) -> #REF!
A12: PERKIN'S | B12: =SUM(#REF!) -> #REF! | C12: =SUM(#REF!) -> #REF! | D12: =SUM(#REF!) -> #REF! | E12: =SUM(#REF!) -> #REF! | F12: =SUM(#REF!) -> #REF! | G12: =SUM(#REF!) -> #REF! | H12: =SUM(#REF!) -> #REF! | I12: =SUM(#REF!) -> #REF! | ... AC12: =SUM(#REF!) -> #REF! | AD12: =SUM(B12:AC12) -> #REF!
A13: Y9T | B13: =SUM(#REF!,#REF!,#REF!,#REF!,#REF!) -> #REF! | C13: =SUM(#REF!,#REF!,#REF!,#REF!,#REF!) -> #REF! | D13: =SUM(#REF!,#REF!,#REF!,#REF!,#REF!) -> #REF! | E13: =SUM(#REF!,#REF!,#REF!,#REF!,#REF!) -> #REF! | F13: =SUM(#REF!,#REF!,#REF!,#REF!,#REF!) -> #REF! | G13: =SUM(#REF!,#REF!,#REF!,#REF!,#REF!) -> #REF! | H13: =SUM(#REF!,#REF!,#REF!,#REF!,#REF!) -> #REF! | I13: =SUM(#REF!,#REF!,#REF!,#REF!,#REF!) -> #REF! | ... AC13: =SUM(#REF!,#REF!,#REF!,#REF!,#REF!) -> #REF! | AD13: =SUM(B13:AC13) -> #REF!
A14: YXA | B14: =SUM(#REF!,#REF!,#REF!) -> #REF! | C14: =SUM(#REF!,#REF!,#REF!) -> #REF! | D14: =SUM(#REF!,#REF!,#REF!) -> #REF! | E14: =SUM(#REF!,#REF!,#REF!) -> #REF! | F14: =SUM(#REF!,#REF!,#REF!) -> #REF! | G14: =SUM(#REF!,#REF!,#REF!) -> #REF! | H14: =SUM(#REF!,#REF!,#REF!) -> #REF! | I14: =SUM(#REF!,#REF!,#REF!) -> #REF! | ... AC14: =SUM(#REF!,#REF!,#REF!) -> #REF! | AD14: =SUM(B14:AC14) -> #REF!
A15: Y0M | B15: =SUM(#REF!) -> #REF! | C15: =SUM(#REF!) -> #REF! | D15: =SUM(#REF!) -> #REF! | E15: =SUM(#REF!) -> #REF! | F15: =SUM(#REF!) -> #REF! | G15: =SUM(#REF!) -> #REF! | H15: =SUM(#REF!) -> #REF! | I15: =SUM(#REF!) -> #REF! | ... AC15: =SUM(#REF!) -> #REF! | AD15: =SUM(B15:AC15) -> #REF!
A16: Y17 | B16: =SUM(#REF!) -> #REF! | C16: =SUM(#REF!) -> #REF! | D16: =SUM(#REF!) -> #REF! | E16: =SUM(#REF!) -> #REF! | F16: =SUM(#REF!) -> #REF! | G16: =SUM(#REF!) -> #REF! | H16: =SUM(#REF!) -> #REF! | I16: =SUM(#REF!) -> #REF! | ... AC16: =SUM(#REF!) -> #REF! | AD16: =SUM(B16:AC16) -> #REF!
A17: HONDA | B17: =SUM(#REF!,#REF!) -> #REF! | C17: =SUM(#REF!,#REF!) -> #REF! | D17: =SUM(#REF!,#REF!) -> #REF! | E17: =SUM(#REF!,#REF!) -> #REF! | F17: =SUM(#REF!,#REF!) -> #REF! | G17: =SUM(#REF!,#REF!) -> #REF! | H17: =SUM(#REF!,#REF!) -> #REF! | I17: =SUM(#REF!,#REF!) -> #REF! | ... AC17: =SUM(#REF!,#REF!) -> #REF! | AD17: =SUM(B17:AC17) -> #REF!
A18: YHB /YNC | B18: =SUM(#REF!,#REF!,#REF!,#REF!) -> #REF! | C18: =SUM(#REF!,#REF!,#REF!,#REF!) -> #REF! | D18: =SUM(#REF!,#REF!,#REF!,#REF!) -> #REF! | E18: =SUM(#REF!,#REF!,#REF!,#REF!) -> #REF! | F18: =SUM(#REF!,#REF!,#REF!,#REF!) -> #REF! | G18: =SUM(#REF!,#REF!,#REF!,#REF!) -> #REF! | H18: =SUM(#REF!,#REF!,#REF!,#REF!) -> #REF! | I18: =SUM(#REF!,#REF!,#REF!,#REF!) -> #REF! | ... AC18: =SUM(#REF!,#REF!,#REF!,#REF!) -> #REF! | AD18: =SUM(B18:AC18) -> #REF!
A19: YED NB | B19: =SUM(#REF!,#REF!,#REF!) -> #REF! | C19: =SUM(#REF!,#REF!,#REF!) -> #REF! | D19: =SUM(#REF!,#REF!,#REF!) -> #REF! | E19: =SUM(#REF!,#REF!,#REF!) -> #REF! | F19: =SUM(#REF!,#REF!,#REF!) -> #REF! | G19: =SUM(#REF!,#REF!,#REF!) -> #REF! | H19: =SUM(#REF!,#REF!,#REF!) -> #REF! | I19: =SUM(#REF!,#REF!,#REF!) -> #REF! | ... AC19: =SUM(#REF!,#REF!,#REF!) -> #REF! | AD19: =SUM(B19:AC19) -> #REF!
A20: Total | B20: =SUM(B3:B19) -> #REF! | C20: =SUM(C3:C19) -> #REF! | D20: =SUM(D3:D19) -> #REF! | E20: =SUM(E3:E19) -> #REF! | F20: =SUM(F3:F19) -> #REF! | G20: =SUM(G3:G19) -> #REF! | H20: =SUM(H3:H19) -> #REF! | I20: =SUM(I3:I19) -> #REF! | ... AD20: =SUM(AD3:AD19) -> #REF!
B62: 15022951
F210: 200
A263: 265 | B263: 15017134 | C263: PRS_BRACE FR PILLAR INNER R_63122-53MB0 | D263: YE3K10 | G263: =F263/E263*1000000 -> #DIV/0!
E302: YG8 RC 25
E303: YG8 RC25
B309: 15031405 | D309: PRS_Loc.Ctr Piller Low. L_61221-78U20 | E309: YG8 RC25
D310: PRS_Loc.Ctr Piller Low. R_61211-78U10 | E310: YG8 RC 25
B311: 15031404 | D311: PRS_Loc.Ctr Piller Low. L_61221-78U10 | E311: YG8 RC25

Sheet 1
A1: Monthly Rejection Data May. '2026
A2: S N | B2: SAP CODE | C2: LINE | D2: Material Description | E2: MODEL | F2: Total Inspection | G2: REJECTION | H2: PPM | I2: Crack | J2: Flange Short | K2: Misfeed | L2: Wrinkle | M2: Damage | N2: Dent / Scratch | O2: Overlap | P2: Bending NG | Q2: Flange bend | R2: Hole Oversize | S2: Hole Miss | T2: HOLE VARIANT NG | U2: Op. miss | V2: Scrap Mark | W2: SHOCK LINE | X2: HOLE OUT | Y2: FLANGE CRACK | Z2: FLARING NG | AA2: Rusty | AB2: FLANGE EXCESS | AC2: Raw Material | AD2: Tool Trial | AE2: Customer Return | AF2: Setting | AG2: Others | AJ2: Old rej
A3: 1 | B3: 15017132 | C3: 500 T | D3: PRS_MBR. HOOD LOCK UPPER,58231-72S00 | E3: YHC | G3: =SUM(I3:AJ3) -> 0 | H3: =G3/F3*1000000 -> #DIV/0!
A4: 2 | B4: 15017133 | C4: 500 T | D4: PRS_MBR. HOOD LOCK LOWER,58232-72S00 | E4: YHC | G4: =SUM(I4:AJ4) -> 0 | H4: =G4/F4*1000000 -> #DIV/0!
A5: 3 | B5: 15018331 | C5: PS-3 | D5: REINF SIDE SILL STRENGTH CTR 63234-62S00 | E5: Y1K | G5: =SUM(I5:AJ5) -> 0 | H5: =G5/F5*1000000 -> #DIV/0!
A6: 4 | B6: 15017449 | C6: PS-3 | D6: PRS_EXT. FL SIDE MBR CTR R ,62141-62S00 | E6: Y1K | F6: =VLOOKUP(B6,'[1]Daily production report'!$C$43:$J$96,8,0) -> 800 | G6: =SUM(I6:AJ6) -> 0 | H6: =G6/F6*1000000 -> 0
A7: 5 | B7: 15017450 | C7: PS-3 | D7: PRS_EXT. FL SIDE MBR CTR R ,62341-62S00 | E7: Y1K | F7: =VLOOKUP(B7,'[1]Daily production report'!$C$43:$J$96,8,0) -> 800 | G7: =SUM(I7:AJ7) -> 1 | H7: =G7/F7*1000000 -> 1250 | K7: 1
A8: 6 | B8: 15017143 | C8: 800 T | D8: PRS_REINF REAR SHOK. ABSO L_63814-62S00 | E8: Y1K | G8: =SUM(I8:AJ8) -> 0 | H8: =G8/F8*1000000 -> #DIV/0!
A9: 7 | B9: 15025379 | C9: NPL-1 | D9: PRS_PANEL COWL FRONT_59721-62S00 | E9: Y1K | G9: =SUM(I9:AJ9) -> 0 | H9: =G9/F9*1000000 -> #DIV/0!
A10: 8 | B10: 15025378 | C10: NPL-1 | D10: PRS_PANEL COWL FRONT_59721-62S10 | E10: Y1K | G10: =SUM(I10:AJ10) -> 0 | H10: =G10/F10*1000000 -> #DIV/0!
A11: 9 | B11: 15027116 | C11: 800 T | D11: PRS_PANEL RR WH. HOU IN. R _63411-62S00 | E11: Y1K | F11: =VLOOKUP(B11,'[1]Daily production report'!$C$43:$J$96,8,0) -> 1262 | G11: =SUM(I11:AJ11) -> 0 | H11: =G11/F11*1000000 -> 0
A12: 10 | B12: 15027117 | C12: 800 T | D12: PRS_PANEL RR WH. HOU IN. R _63811-62S00 | E12: Y1K | F12: =VLOOKUP(B12,'[1]Daily production report'!$C$43:$J$96,8,0) -> 1262 | G12: =SUM(I12:AJ12) -> 0 | H12: =G12/F12*1000000 -> 0
A13: 11 | B13: 15017140 | C13: NPL-1 | D13: PRS_PANEL WH HOU IN RR R_63413-62S00 | E13: Y1K | F13: =VLOOKUP(B13,'[1]Daily production report'!$C$43:$J$96,8,0) -> 350 | G13: =SUM(I13:AJ13) -> 1 | H13: =G13/F13*1000000 -> 2857.1429 | K13: 1
A14: 12 | B14: 15017141 | C14: NPL-1 | D14: PRS_PANEL WH HOU IN RR L_63813-62S00 | E14: Y1K | F14: =VLOOKUP(B14,'[1]Daily production report'!$C$43:$J$96,8,0) -> 350 | G14: =SUM(I14:AJ14) -> 1 | H14: =G14/F14*1000000 -> 2857.1429 | K14: 1
A15: 13 | B15: 15017142 | C15: 800 T | D15: PRS_REINF REAR SHOK. ABSO R_63414-62S00 | E15: Y1K | G15: =SUM(I15:AJ15) -> 0 | H15: =G15/F15*1000000 -> #DIV/0!
A16: 14 | B16: 15017144 | C16: PS-3 | D16: PRS_PANEL FR. PIL. INR FR R_63111-62S00 | E16: Y1K | G16: =SUM(I16:AJ16) -> 0 | H16: =G16/F16*1000000 -> #DIV/0!
A17: 15 | B17: 15017145 | C17: PS-3 | D17: PRS_PANEL FR. PIL. INR FR L_65111-62S00 | E17: Y1K | G17: =SUM(I17:AJ17) -> 0 | H17: =G17/F17*1000000 -> #DIV/0!
A18: 16 | B18: 15017146 | C18: 800 T | D18: PRS_PANEL FR. PIL. INR RR R_63113-62S00 | E18: Y1K | F18: =VLOOKUP(B18,'[1]Daily production report'!$C$43:$J$96,8,0) -> 1729 | G18: =SUM(I18:AJ18) -> 0 | H18: =G18/F18*1000000 -> 0
A19: 17 | B19: 15017147 | C19: 800 T | D19: PRS_PANEL FR. PIL. INR RR L_63513-62S00 | E19: Y1K | F19: =VLOOKUP(B19,'[1]Daily production report'!$C$43:$J$96,8,0) -> 1729 | G19: =SUM(I19:AJ19) -> 0 | H19: =G19/F19*1000000 -> 0
A20: 18 | B20: 15017148 | C20: NPL-2 | D20: PRS_RAIL ROOF SIDE INNER R_ 63121-62S00 | E20: Y1K | G20: =SUM(I20:AJ20) -> 0 | H20: =G20/F20*1000000 -> #DIV/0!
A21: 19 | B21: 15017149 | C21: NPL-2 | D21: PRS_RAIL ROOF SIDE INNER L_ 63521-62S00 | E21: Y1K | G21: =SUM(I21:AJ21) -> 0 | H21: =G21/F21*1000000 -> #DIV/0!
A22: 20 | B22: 15017150 | C22: 800 T | D22: PRS_MBR. RR FL. SIDE FR R _62111-62S00 | E22: Y1K | G22: =SUM(I22:AJ22) -> 0 | H22: =G22/F22*1000000 -> #DIV/0!
A23: 21 | B23: 15017151 | C23: 800 T | D23: PRS_MBR. RR FL. SIDE FR L _62311-62S00 | E23: Y1K | G23: =SUM(I23:AJ23) -> 0 | H23: =G23/F23*1000000 -> #DIV/0!
A24: 22 | B24: 15017152 | C24: PS-3 | D24: PRS_EXT RR FLR S MBR FR R _62116-62S00 | E24: Y1K | G24: =SUM(I24:AJ24) -> 0 | H24: =G24/F24*1000000 -> #DIV/0!
A25: 23 | B25: 15017153 | C25: PS-3 | D25: PRS_EXT RR FLR S MBR FR R _62316-62S00 | E25: Y1K | G25: =SUM(I25:AJ25) -> 0 | H25: =G25/F25*1000000 -> #DIV/0!
A26: 24 | B26: 15017154 | C26: NPL-2 | D26: PRS_COMPARTMENT REAR FLOOR R_62211-62S00 | E26: Y1K | G26: =SUM(I26:AJ26) -> 0 | H26: =G26/F26*1000000 -> #DIV/0!
A27: 25 | B27: 15017155 | C27: NPL-2 | D27: PRS_COMPARTMENT REAR FLOOR L_62411-62S00 | E27: Y1K | G27: =SUM(I27:AJ27) -> 0 | H27: =G27/F27*1000000 -> #DIV/0!
A28: 26 | B28: 15027104 | C28: 800 T | D28: PRS_PANEL RR FLOOR SEAT MTG_61531-62S00 | E28: Y1K | G28: =SUM(I28:AJ28) -> 0 | H28: =G28/F28*1000000 -> #DIV/0!
A29: 27 | B29: 15017157 | C29: 800 T | D29: PRS_PANEL RR FLOOR SEAT MTG_61531-62S10 | E29: Y1K | G29: =SUM(I29:AJ29) -> 0 | H29: =G29/F29*1000000 -> #DIV/0!
A30: 28 | B30: 15017158 | C30: 800 T | D30: PRS_STRENGTH SIDE SILL FR R_63231-62S00 | E30: Y1K | G30: =SUM(I30:AJ30) -> 0 | H30: =G30/F30*1000000 -> #DIV/0!
A31: 29 | B31: 15017159 | C31: 800 T | D31: PRS_STRENGTH SIDE SILL FR L_63631-62S00 | E31: Y1K | G31: =SUM(I31:AJ31) -> 2 | H31: =G31/F31*1000000 -> #DIV/0! | J31: 2
A32: 30 | B32: 15017160 | C32: NPL-1 | D32: PRS_PANEL COWL UPPER_59711-62S00 | E32: Y1K | G32: =SUM(I32:AJ32) -> 0 | H32: =G32/F32*1000000 -> #DIV/0!
A33: 31 | B33: 15017161 | C33: NPL-1 | D33: PRS_PANEL COWL UPPER_59711-62S10 | E33: Y1K | G33: =SUM(I33:AJ33) -> 0 | H33: =G33/F33*1000000 -> #DIV/0!
A34: 32 | B34: 15017162 | C34: 800 T | D34: PRS_PANEL RR LAMP HOU OUT R_64131-62S00 | E34: Y1K | F34: =VLOOKUP(B34,'[1]Daily production report'!$C$43:$J$96,8,0) -> 847 | G34: =SUM(I34:AJ34) -> 8 | H34: =G34/F34*1000000 -> 9445.1004 | K34: 8
A35: 33 | B35: 15020546 | C35: 800 T | D35: PRS_PANEL RR LAMP HOU OUT L_64531-62S00 | E35: Y1K | F35: =VLOOKUP(B35,'[1]Daily production report'!$C$43:$J$96,8,0) -> 1588 | G35: =SUM(I35:AJ35) -> 8 | H35: =G35/F35*1000000 -> 5037.7834 | O35: 8
A36: 34 | B36: 15030388 | C36: 500 T | D36: PRS_58311-62S01_YOM/Y1K | E36: Y1K ECN | G36: =SUM(I36:AJ36) -> 0 | H36: =G36/F36*1000000 -> #DIV/0!
A37: 35 | B37: 15030389 | C37: 500 T | D37: PRS_58411-62S01_YOM/Y1K | E37: Y1K ECN | G37: =SUM(I37:AJ37) -> 0 | H37: =G37/F37*1000000 -> #DIV/0!
A38: 36 | B38: 15017166 | C38: PS-3 | D38: PRS_EXTENSION APRON FRONT R_58313-62S00 | E38: Y1K | G38: =SUM(I38:AJ38) -> 0 | H38: =G38/F38*1000000 -> #DIV/0!
A39: 37 | B39: 15017167 | C39: PS-3 | D39: PRS_EXTENSION APRON FRONT L_58413-62S00 | E39: Y1K | G39: =SUM(I39:AJ39) -> 0 | H39: =G39/F39*1000000 -> #DIV/0!
A40: 38 | B40: 15017168 | C40: PS-3 | D40: PRS_MEMBER APRON FRONT R_58314-62S00 | E40: Y1K | G40: =SUM(I40:AJ40) -> 0 | H40: =G40/F40*1000000 -> #DIV/0!
...

Sheet 2
A1: Monthly Rejection Data May. '2026
A2: S N | B2: S.NO | C2: LINE | D2: Material Description | E2: MODEL | F2: Total Inspection | G2: REJECTION | H2: PPM | I2: Crack | J2: Flange Short | K2: Misfeed | L2: Wrinkle | M2: Damage | N2: Dent / Scratch | O2: Overlap | P2: Bending NG | Q2: Flange bend | R2: Hole Oversize | S2: Hole Miss | T2: HOLE VARIANT NG | U2: Op. miss | V2: Scrap Mark | W2: SHOCK LINE | X2: HOLE OUT | Y2: FLANGE CRACK | Z2: FLARING NG | AA2: Rusty | AB2: FLANGE EXCESS | AC2: Raw Material | AD2: Tool Trial | AE2: Customer Return | AF2: Setting | AG2: Others | AJ2: Old rej
A3: 1 | B3: 15017132 | C3: 500 T | D3: PRS_MBR. HOOD LOCK UPPER,58231-72S00 | E3: YHC | G3: =SUM(I3:AJ3) -> 0 | H3: =G3/F3*1000000 -> #DIV/0!
A4: 2 | B4: 15017133 | C4: 500 T | D4: PRS_MBR. HOOD LOCK LOWER,58232-72S00 | E4: YHC | G4: =SUM(I4:AJ4) -> 0 | H4: =G4/F4*1000000 -> #DIV/0!
A5: 3 | B5: 15018331 | C5: PS-3 | D5: REINF SIDE SILL STRENGTH CTR 63234-62S00 | E5: Y1K | G5: =SUM(I5:AJ5) -> 0 | H5: =G5/F5*1000000 -> #DIV/0!
A6: 4 | B6: 15017449 | C6: PS-3 | D6: PRS_EXT. FL SIDE MBR CTR R ,62141-62S00 | E6: Y1K | G6: =SUM(I6:AJ6) -> 0 | H6: =G6/F6*1000000 -> #DIV/0!
A7: 5 | B7: 15017450 | C7: PS-3 | D7: PRS_EXT. FL SIDE MBR CTR R ,62341-62S00 | E7: Y1K | G7: =SUM(I7:AJ7) -> 0 | H7: =G7/F7*1000000 -> #DIV/0!
A8: 6 | B8: 15017143 | C8: 800 T | D8: PRS_REINF REAR SHOK. ABSO L_63814-62S00 | E8: Y1K | G8: =SUM(I8:AJ8) -> 0 | H8: =G8/F8*1000000 -> #DIV/0!
A9: 7 | B9: 15025379 | C9: NPL-1 | D9: PRS_PANEL COWL FRONT_59721-62S00 | E9: Y1K | G9: =SUM(I9:AJ9) -> 0 | H9: =G9/F9*1000000 -> #DIV/0!
A10: 8 | B10: 15025378 | C10: NPL-1 | D10: PRS_PANEL COWL FRONT_59721-62S10 | E10: Y1K | G10: =SUM(I10:AJ10) -> 0 | H10: =G10/F10*1000000 -> #DIV/0!
A11: 9 | B11: 15027116 | C11: 800 T | D11: PRS_PANEL RR WH. HOU IN. R _63411-62S00 | E11: Y1K | G11: =SUM(I11:AJ11) -> 0 | H11: =G11/F11*1000000 -> #DIV/0!
A12: 10 | B12: 15027117 | C12: 800 T | D12: PRS_PANEL RR WH. HOU IN. R _63811-62S00 | E12: Y1K | G12: =SUM(I12:AJ12) -> 0 | H12: =G12/F12*1000000 -> #DIV/0!
A13: 11 | B13: 15017140 | C13: NPL-1 | D13: PRS_PANEL WH HOU IN RR R_63413-62S00 | E13: Y1K | F13: =VLOOKUP(B13,'[3]Daily production report'!$C$43:$J$91,8,0) -> 143 | G13: =SUM(I13:AJ13) -> 0 | H13: =G13/F13*1000000 -> 0
A14: 12 | B14: 15017141 | C14: NPL-1 | D14: PRS_PANEL WH HOU IN RR L_63813-62S00 | E14: Y1K | F14: =VLOOKUP(B14,'[3]Daily production report'!$C$43:$J$91,8,0) -> 143 | G14: =SUM(I14:AJ14) -> 0 | H14: =G14/F14*1000000 -> 0
A15: 13 | B15: 15017142 | C15: 800 T | D15: PRS_REINF REAR SHOK. ABSO R_63414-62S00 | E15: Y1K | G15: =SUM(I15:AJ15) -> 0 | H15: =G15/F15*1000000 -> #DIV/0!
A16: 14 | B16: 15017144 | C16: PS-3 | D16: PRS_PANEL FR. PIL. INR FR R_63111-62S00 | E16: Y1K | G16: =SUM(I16:AJ16) -> 0 | H16: =G16/F16*1000000 -> #DIV/0!
A17: 15 | B17: 15017145 | C17: PS-3 | D17: PRS_PANEL FR. PIL. INR FR L_65111-62S00 | E17: Y1K | G17: =SUM(I17:AJ17) -> 0 | H17: =G17/F17*1000000 -> #DIV/0!
A18: 16 | B18: 15017146 | C18: 800 T | D18: PRS_PANEL FR. PIL. INR RR R_63113-62S00 | E18: Y1K | G18: =SUM(I18:AJ18) -> 0 | H18: =G18/F18*1000000 -> #DIV/0!
A19: 17 | B19: 15017147 | C19: 800 T | D19: PRS_PANEL FR. PIL. INR RR L_63513-62S00 | E19: Y1K | G19: =SUM(I19:AJ19) -> 0 | H19: =G19/F19*1000000 -> #DIV/0!
A20: 18 | B20: 15017148 | C20: NPL-2 | D20: PRS_RAIL ROOF SIDE INNER R_ 63121-62S00 | E20: Y1K | F20: =VLOOKUP(B20,'[3]Daily production report'!$C$43:$J$91,8,0) -> 185 | G20: =SUM(I20:AJ20) -> 0 | H20: =G20/F20*1000000 -> 0
A21: 19 | B21: 15017149 | C21: NPL-2 | D21: PRS_RAIL ROOF SIDE INNER L_ 63521-62S00 | E21: Y1K | F21: =VLOOKUP(B21,'[3]Daily production report'!$C$43:$J$91,8,0) -> 185 | G21: =SUM(I21:AJ21) -> 0 | H21: =G21/F21*1000000 -> 0
A22: 20 | B22: 15017150 | C22: 800 T | D22: PRS_MBR. RR FL. SIDE FR R _62111-62S00 | E22: Y1K | G22: =SUM(I22:AJ22) -> 0 | H22: =G22/F22*1000000 -> #DIV/0!
A23: 21 | B23: 15017151 | C23: 800 T | D23: PRS_MBR. RR FL. SIDE FR L _62311-62S00 | E23: Y1K | G23: =SUM(I23:AJ23) -> 0 | H23: =G23/F23*1000000 -> #DIV/0!
A24: 22 | B24: 15017152 | C24: PS-3 | D24: PRS_EXT RR FLR S MBR FR R _62116-62S00 | E24: Y1K | G24: =SUM(I24:AJ24) -> 0 | H24: =G24/F24*1000000 -> #DIV/0!
A25: 23 | B25: 15017153 | C25: PS-3 | D25: PRS_EXT RR FLR S MBR FR R _62316-62S00 | E25: Y1K | G25: =SUM(I25:AJ25) -> 0 | H25: =G25/F25*1000000 -> #DIV/0!
A26: 24 | B26: 15017154 | C26: NPL-2 | D26: PRS_COMPARTMENT REAR FLOOR R_62211-62S00 | E26: Y1K | G26: =SUM(I26:AJ26) -> 0 | H26: =G26/F26*1000000 -> #DIV/0!
A27: 25 | B27: 15017155 | C27: NPL-2 | D27: PRS_COMPARTMENT REAR FLOOR L_62411-62S00 | E27: Y1K | G27: =SUM(I27:AJ27) -> 0 | H27: =G27/F27*1000000 -> #DIV/0!
A28: 26 | B28: 15027104 | C28: 800 T | D28: PRS_PANEL RR FLOOR SEAT MTG_61531-62S00 | E28: Y1K | G28: =SUM(I28:AJ28) -> 0 | H28: =G28/F28*1000000 -> #DIV/0!
A29: 27 | B29: 15017157 | C29: 800 T | D29: PRS_PANEL RR FLOOR SEAT MTG_61531-62S10 | E29: Y1K | G29: =SUM(I29:AJ29) -> 0 | H29: =G29/F29*1000000 -> #DIV/0!
A30: 28 | B30: 15017158 | C30: 800 T | D30: PRS_STRENGTH SIDE SILL FR R_63231-62S00 | E30: Y1K | G30: =SUM(I30:AJ30) -> 0 | H30: =G30/F30*1000000 -> #DIV/0!
A31: 29 | B31: 15017159 | C31: 800 T | D31: PRS_STRENGTH SIDE SILL FR L_63631-62S00 | E31: Y1K | F31: =VLOOKUP(B31,'[3]Daily production report'!$C$43:$J$91,8,0) -> 890 | G31: =SUM(I31:AJ31) -> 0 | H31: =G31/F31*1000000 -> 0
A32: 30 | B32: 15017160 | C32: NPL-1 | D32: PRS_PANEL COWL UPPER_59711-62S00 | E32: Y1K | F32: =VLOOKUP(B32,'[3]Daily production report'!$C$43:$J$91,8,0) -> 775 | G32: =SUM(I32:AJ32) -> 0 | H32: =G32/F32*1000000 -> 0
A33: 31 | B33: 15017161 | C33: NPL-1 | D33: PRS_PANEL COWL UPPER_59711-62S10 | E33: Y1K | G33: =SUM(I33:AJ33) -> 0 | H33: =G33/F33*1000000 -> #DIV/0!
A34: 32 | B34: 15017162 | C34: 800 T | D34: PRS_PANEL RR LAMP HOU OUT R_64131-62S00 | E34: Y1K | F34: =VLOOKUP(B34,'[3]Daily production report'!$C$43:$J$91,8,0) -> 568 | G34: =SUM(I34:AJ34) -> 7 | H34: =G34/F34*1000000 -> 12323.944 | K34: 7
A35: 33 | B35: 15020546 | C35: 800 T | D35: PRS_PANEL RR LAMP HOU OUT L_64531-62S00 | E35: Y1K | G35: =SUM(I35:AJ35) -> 0 | H35: =G35/F35*1000000 -> #DIV/0!
A36: 34 | B36: 15030388 | C36: 500 T | D36: PRS_58311-62S01_YOM/Y1K | E36: Y1K ECN | F36: =VLOOKUP(B36,'[3]Daily production report'!$C$43:$J$91,8,0) -> 1270 | G36: =SUM(I36:AJ36) -> 0 | H36: =G36/F36*1000000 -> 0
A37: 35 | B37: 15030389 | C37: 500 T | D37: PRS_58411-62S01_YOM/Y1K | E37: Y1K ECN | F37: =VLOOKUP(B37,'[3]Daily production report'!$C$43:$J$91,8,0) -> 1270 | G37: =SUM(I37:AJ37) -> 0 | H37: =G37/F37*1000000 -> 0
A38: 36 | B38: 15017166 | C38: PS-3 | D38: PRS_EXTENSION APRON FRONT R_58313-62S00 | E38: Y1K | G38: =SUM(I38:AJ38) -> 0 | H38: =G38/F38*1000000 -> #DIV/0!
A39: 37 | B39: 15017167 | C39: PS-3 | D39: PRS_EXTENSION APRON FRONT L_58413-62S00 | E39: Y1K | G39: =SUM(I39:AJ39) -> 0 | H39: =G39/F39*1000000 -> #DIV/0!
A40: 38 | B40: 15017168 | C40: PS-3 | D40: PRS_MEMBER APRON FRONT R_58314-62S00 | E40: Y1K | G40: =SUM(I40:AJ40) -> 0 | H40: =G40/F40*1000000 -> #DIV/0!
...

Sheet  (3)
A1: Monthly Rejection Data May. '2026
A2: S N | B2: SAP CODE | C2: LINE | D2: Material Description | E2: MODEL | F2: Total Inspection | G2: REJECTION | H2: PPM | I2: Crack | J2: Flange Short | K2: Misfeed | L2: Wrinkle | M2: Damage | N2: Dent / Scratch | O2: Overlap | P2: Bending NG | Q2: Flange bend | R2: Hole Oversize | S2: Hole Miss | T2: HOLE VARIANT NG | U2: Op. miss | V2: Scrap Mark | W2: SHOCK LINE | X2: HOLE OUT | Y2: FLANGE CRACK | Z2: FLARING NG | AA2: Rusty | AB2: FLANGE EXCESS | AC2: Raw Material | AD2: Tool Trial | AE2: Customer Return | AF2: Setting | AG2: Others | AJ2: Old rej
A3: 1 | B3: 15017132 | C3: 500 T | D3: PRS_MBR. HOOD LOCK UPPER,58231-72S00 | E3: YHC | G3: =SUM(I3:AJ3) -> 0 | H3: =G3/F3*1000000 -> #DIV/0!
A4: 2 | B4: 15017133 | C4: 500 T | D4: PRS_MBR. HOOD LOCK LOWER,58232-72S00 | E4: YHC | G4: =SUM(I4:AJ4) -> 0 | H4: =G4/F4*1000000 -> #DIV/0!
A5: 3 | B5: 15018331 | C5: PS-3 | D5: REINF SIDE SILL STRENGTH CTR 63234-62S00 | E5: Y1K | G5: =SUM(I5:AJ5) -> 0 | H5: =G5/F5*1000000 -> #DIV/0!
A6: 4 | B6: 15017449 | C6: PS-3 | D6: PRS_EXT. FL SIDE MBR CTR R ,62141-62S00 | E6: Y1K | G6: =SUM(I6:AJ6) -> 0 | H6: =G6/F6*1000000 -> #DIV/0!
A7: 5 | B7: 15017450 | C7: PS-3 | D7: PRS_EXT. FL SIDE MBR CTR R ,62341-62S00 | E7: Y1K | G7: =SUM(I7:AJ7) -> 0 | H7: =G7/F7*1000000 -> #DIV/0!
A8: 6 | B8: 15017143 | C8: 800 T | D8: PRS_REINF REAR SHOK. ABSO L_63814-62S00 | E8: Y1K | G8: =SUM(I8:AJ8) -> 0 | H8: =G8/F8*1000000 -> #DIV/0!
A9: 7 | B9: 15025379 | C9: NPL-1 | D9: PRS_PANEL COWL FRONT_59721-62S00 | E9: Y1K | G9: =SUM(I9:AJ9) -> 10 | H9: =G9/F9*1000000 -> #DIV/0! | AG9: 10
A10: 8 | B10: 15025378 | C10: NPL-1 | D10: PRS_PANEL COWL FRONT_59721-62S10 | E10: Y1K | G10: =SUM(I10:AJ10) -> 0 | H10: =G10/F10*1000000 -> #DIV/0!
A11: 9 | B11: 15027116 | C11: 800 T | D11: PRS_PANEL RR WH. HOU IN. R _63411-62S00 | E11: Y1K | G11: =SUM(I11:AJ11) -> 0 | H11: =G11/F11*1000000 -> #DIV/0!
A12: 10 | B12: 15027117 | C12: 800 T | D12: PRS_PANEL RR WH. HOU IN. R _63811-62S00 | E12: Y1K | G12: =SUM(I12:AJ12) -> 0 | H12: =G12/F12*1000000 -> #DIV/0!
A13: 11 | B13: 15017140 | C13: NPL-1 | D13: PRS_PANEL WH HOU IN RR R_63413-62S00 | E13: Y1K | G13: =SUM(I13:AJ13) -> 0 | H13: =G13/F13*1000000 -> #DIV/0!
A14: 12 | B14: 15017141 | C14: NPL-1 | D14: PRS_PANEL WH HOU IN RR L_63813-62S00 | E14: Y1K | G14: =SUM(I14:AJ14) -> 0 | H14: =G14/F14*1000000 -> #DIV/0!
A15: 13 | B15: 15017142 | C15: 800 T | D15: PRS_REINF REAR SHOK. ABSO R_63414-62S00 | E15: Y1K | G15: =SUM(I15:AJ15) -> 0 | H15: =G15/F15*1000000 -> #DIV/0!
A16: 14 | B16: 15017144 | C16: PS-3 | D16: PRS_PANEL FR. PIL. INR FR R_63111-62S00 | E16: Y1K | G16: =SUM(I16:AJ16) -> 0 | H16: =G16/F16*1000000 -> #DIV/0!
A17: 15 | B17: 15017145 | C17: PS-3 | D17: PRS_PANEL FR. PIL. INR FR L_65111-62S00 | E17: Y1K | G17: =SUM(I17:AJ17) -> 0 | H17: =G17/F17*1000000 -> #DIV/0!
A18: 16 | B18: 15017146 | C18: 800 T | D18: PRS_PANEL FR. PIL. INR RR R_63113-62S00 | E18: Y1K | G18: =SUM(I18:AJ18) -> 0 | H18: =G18/F18*1000000 -> #DIV/0!
A19: 17 | B19: 15017147 | C19: 800 T | D19: PRS_PANEL FR. PIL. INR RR L_63513-62S00 | E19: Y1K | G19: =SUM(I19:AJ19) -> 0 | H19: =G19/F19*1000000 -> #DIV/0!
A20: 18 | B20: 15017148 | C20: NPL-2 | D20: PRS_RAIL ROOF SIDE INNER R_ 63121-62S00 | E20: Y1K | G20: =SUM(I20:AJ20) -> 0 | H20: =G20/F20*1000000 -> #DIV/0!
A21: 19 | B21: 15017149 | C21: NPL-2 | D21: PRS_RAIL ROOF SIDE INNER L_ 63521-62S00 | E21: Y1K | G21: =SUM(I21:AJ21) -> 0 | H21: =G21/F21*1000000 -> #DIV/0!
A22: 20 | B22: 15017150 | C22: 800 T | D22: PRS_MBR. RR FL. SIDE FR R _62111-62S00 | E22: Y1K | F22: =VLOOKUP(B22,'[4]Daily production report'!$C$43:$J$78,8,0) -> 2355 | G22: =SUM(I22:AJ22) -> 0 | H22: =G22/F22*1000000 -> 0
A23: 21 | B23: 15017151 | C23: 800 T | D23: PRS_MBR. RR FL. SIDE FR L _62311-62S00 | E23: Y1K | F23: =VLOOKUP(B23,'[4]Daily production report'!$C$43:$J$78,8,0) -> 2000 | G23: =SUM(I23:AJ23) -> 0 | H23: =G23/F23*1000000 -> 0
A24: 22 | B24: 15017152 | C24: PS-3 | D24: PRS_EXT RR FLR S MBR FR R _62116-62S00 | E24: Y1K | G24: =SUM(I24:AJ24) -> 0 | H24: =G24/F24*1000000 -> #DIV/0!
A25: 23 | B25: 15017153 | C25: PS-3 | D25: PRS_EXT RR FLR S MBR FR R _62316-62S00 | E25: Y1K | G25: =SUM(I25:AJ25) -> 0 | H25: =G25/F25*1000000 -> #DIV/0!
A26: 24 | B26: 15017154 | C26: NPL-2 | D26: PRS_COMPARTMENT REAR FLOOR R_62211-62S00 | E26: Y1K | G26: =SUM(I26:AJ26) -> 0 | H26: =G26/F26*1000000 -> #DIV/0!
A27: 25 | B27: 15017155 | C27: NPL-2 | D27: PRS_COMPARTMENT REAR FLOOR L_62411-62S00 | E27: Y1K | G27: =SUM(I27:AJ27) -> 0 | H27: =G27/F27*1000000 -> #DIV/0!
A28: 26 | B28: 15027104 | C28: 800 T | D28: PRS_PANEL RR FLOOR SEAT MTG_61531-62S00 | E28: Y1K | G28: =SUM(I28:AJ28) -> 0 | H28: =G28/F28*1000000 -> #DIV/0!
A29: 27 | B29: 15017157 | C29: 800 T | D29: PRS_PANEL RR FLOOR SEAT MTG_61531-62S10 | E29: Y1K | G29: =SUM(I29:AJ29) -> 0 | H29: =G29/F29*1000000 -> #DIV/0!
A30: 28 | B30: 15017158 | C30: 800 T | D30: PRS_STRENGTH SIDE SILL FR R_63231-62S00 | E30: Y1K | G30: =SUM(I30:AJ30) -> 0 | H30: =G30/F30*1000000 -> #DIV/0!
A31: 29 | B31: 15017159 | C31: 800 T | D31: PRS_STRENGTH SIDE SILL FR L_63631-62S00 | E31: Y1K | G31: =SUM(I31:AJ31) -> 0 | H31: =G31/F31*1000000 -> #DIV/0!
A32: 30 | B32: 15017160 | C32: NPL-1 | D32: PRS_PANEL COWL UPPER_59711-62S00 | E32: Y1K | F32: =VLOOKUP(B32,'[4]Daily production report'!$C$43:$J$78,8,0) -> 450 | G32: =SUM(I32:AJ32) -> 0 | H32: =G32/F32*1000000 -> 0
A33: 31 | B33: 15017161 | C33: NPL-1 | D33: PRS_PANEL COWL UPPER_59711-62S10 | E33: Y1K | G33: =SUM(I33:AJ33) -> 0 | H33: =G33/F33*1000000 -> #DIV/0!
A34: 32 | B34: 15017162 | C34: 800 T | D34: PRS_PANEL RR LAMP HOU OUT R_64131-62S00 | E34: Y1K | G34: =SUM(I34:AJ34) -> 0 | H34: =G34/F34*1000000 -> #DIV/0!
A35: 33 | B35: 15020546 | C35: 800 T | D35: PRS_PANEL RR LAMP HOU OUT L_64531-62S00 | E35: Y1K | G35: =SUM(I35:AJ35) -> 10 | H35: =G35/F35*1000000 -> #DIV/0! | I35: 10
A36: 34 | B36: 15030388 | C36: 500 T | D36: PRS_58311-62S01_YOM/Y1K | E36: Y1K ECN | G36: =SUM(I36:AJ36) -> 1 | H36: =G36/F36*1000000 -> #DIV/0! | L36: 1
A37: 35 | B37: 15030389 | C37: 500 T | D37: PRS_58411-62S01_YOM/Y1K | E37: Y1K ECN | G37: =SUM(I37:AJ37) -> 6 | H37: =G37/F37*1000000 -> #DIV/0! | L37: 6
A38: 36 | B38: 15017166 | C38: PS-3 | D38: PRS_EXTENSION APRON FRONT R_58313-62S00 | E38: Y1K | F38: =VLOOKUP(B38,'[4]Daily production report'!$C$43:$J$78,8,0) -> 448 | G38: =SUM(I38:AJ38) -> 0 | H38: =G38/F38*1000000 -> 0
A39: 37 | B39: 15017167 | C39: PS-3 | D39: PRS_EXTENSION APRON FRONT L_58413-62S00 | E39: Y1K | F39: =VLOOKUP(B39,'[4]Daily production report'!$C$43:$J$78,8,0) -> 448 | G39: =SUM(I39:AJ39) -> 0 | H39: =G39/F39*1000000 -> 0
A40: 38 | B40: 15017168 | C40: PS-3 | D40: PRS_MEMBER APRON FRONT R_58314-62S00 | E40: Y1K | G40: =SUM(I40:AJ40) -> 0 | H40: =G40/F40*1000000 -> #DIV/0!
...

Sheet  (4)
A1: Monthly Rejection Data May. '2026
A2: S N | B2: SAP CODE | C2: LINE | D2: Material Description | E2: MODEL | F2: Total Inspection | G2: REJECTION | H2: PPM | I2: Crack | J2: Flange Short | K2: Misfeed | L2: Wrinkle | M2: Damage | N2: Dent / Scratch | O2: Overlap | P2: Bending NG | Q2: Flange bend | R2: Hole Oversize | S2: Hole Miss | T2: HOLE VARIANT NG | U2: Op. miss | V2: Scrap Mark | W2: SHOCK LINE | X2: HOLE OUT | Y2: FLANGE CRACK | Z2: FLARING NG | AA2: Rusty | AB2: FLANGE EXCESS | AC2: Raw Material | AD2: Tool Trial | AE2: Customer Return | AF2: Setting | AG2: Others | AJ2: Old rej
A3: 1 | B3: 15017132 | C3: 500 T | D3: PRS_MBR. HOOD LOCK UPPER,58231-72S00 | E3: YHC | G3: =SUM(I3:AJ3) -> 0 | H3: =G3/F3*1000000 -> #DIV/0!
A4: 2 | B4: 15017133 | C4: 500 T | D4: PRS_MBR. HOOD LOCK LOWER,58232-72S00 | E4: YHC | F4: =VLOOKUP(B4,'[5]Daily production report'!$C$43:$J$95,8,0) -> 300 | G4: =SUM(I4:AJ4) -> 0 | H4: =G4/F4*1000000 -> 0
A5: 3 | B5: 15018331 | C5: PS-3 | D5: REINF SIDE SILL STRENGTH CTR 63234-62S00 | E5: Y1K | G5: =SUM(I5:AJ5) -> 0 | H5: =G5/F5*1000000 -> #DIV/0!
A6: 4 | B6: 15017449 | C6: PS-3 | D6: PRS_EXT. FL SIDE MBR CTR R ,62141-62S00 | E6: Y1K | F6: =VLOOKUP(B6,'[5]Daily production report'!$C$43:$J$95,8,0) -> 945 | G6: =SUM(I6:AJ6) -> 0 | H6: =G6/F6*1000000 -> 0
